Workbook

Sheet Dashboard Overview
B2: 📊 Dashboard Overview — ภาพรวมการเงินรายปี
B3: ="ข้อมูลปี ค.ศ. "&$P$3&" (พ.ศ. "&($P$3+543)&") · ระบบสรุปอัตโนมัติจากหน้า Transaction" | M3: เลือกปี (ค.ศ.) ▸ | P3: 2026
B5: 💰 รายรับรวม | D5: 💸 รายจ่ายรวม | G5: 🏦 เงินออมรวม | J5: 💵 คงเหลือ (Cash Flow) | M5: 📈 อัตราการออม | P5: 🗓️ เดือนที่มีข้อมูล
B6: =$C$23 | D6: =$D$23 | G6: =$E$23 | J6: =$F$23 | M6: =IF($C$23=0,0,$E$23/$C$23) | P6: =SUMPRODUCT(--(($C$11:$C$22+$D$11:$D$22+$E$11:$E$22)>0))
B7: =$C$24 | D7: =$D$24 | G7: =$E$24 | J7: =$F$24 | M7: =IF($C$23=0,"ยังไม่มีรายรับในปีนี้","ใช้จ่าย "&TEXT($D$23/$C$23,"0%")&" ของรายรับ") | P7: =TEXT(COUNTIFS(Transaction!$B:$B,">="&DATE($P$3,1,1),Transaction!$B:$B,"<"&DATE($P$3+1,1,1)),"#,##0")&" รายการ"
B9: 📅 สรุปรายเดือน
B10: เดือน | C10: รายรับ | D10: รายจ่าย | E10: เงินออม | F10: คงเหลือ | G10: อัตราออม | H10: คงเหลือสะสม
B11: ม.ค. | C11: =SUMIFS(Transaction!$E:$E,Transaction!$C:$C,"รายรับ",Transaction!$B:$B,">="&DATE($P$3,MATCH($B11,Setup!$J$6:$J$17,0),1),Transaction!$B:$B,"<"&DATE($P$3,MATCH($B11,Setup!$J$6:$J$17,0)+1,1)) | D11: =SUMIFS(Transaction!$E:$E,Transaction!$C:$C,"รายจ่าย",Transaction!$B:$B,">="&DATE($P$3,MATCH($B11,Setup!$J$6:$J$17,0),1),Transaction!$B:$B,"<"&DATE($P$3,MATCH($B11,Setup!$J$6:$J$17,0)+1,1)) | E11: =SUMIFS(Transaction!$E:$E,Transaction!$C:$C,"เงินออม",Transaction!$B:$B,">="&DATE($P$3,MATCH($B11,Setup!$J$6:$J$17,0),1),Transaction!$B:$B,"<"&DATE($P$3,MATCH($B11,Setup!$J$6:$J$17,0)+1,1)) | F11: =C11-D11-E11 | G11: =IF(C11=0,"",E11/C11) | H11: =IF(C11+D11+E11=0,"",SUM($F$11:F11))
B12: ก.พ. | C12: =SUMIFS(Transaction!$E:$E,Transaction!$C:$C,"รายรับ",Transaction!$B:$B,">="&DATE($P$3,MATCH($B12,Setup!$J$6:$J$17,0),1),Transaction!$B:$B,"<"&DATE($P$3,MATCH($B12,Setup!$J$6:$J$17,0)+1,1)) | D12: =SUMIFS(Transaction!$E:$E,Transaction!$C:$C,"รายจ่าย",Transaction!$B:$B,">="&DATE($P$3,MATCH($B12,Setup!$J$6:$J$17,0),1),Transaction!$B:$B,"<"&DATE($P$3,MATCH($B12,Setup!$J$6:$J$17,0)+1,1)) | E12: =SUMIFS(Transaction!$E:$E,Transaction!$C:$C,"เงินออม",Transaction!$B:$B,">="&DATE($P$3,MATCH($B12,Setup!$J$6:$J$17,0),1),Transaction!$B:$B,"<"&DATE($P$3,MATCH($B12,Setup!$J$6:$J$17,0)+1,1)) | F12: =C12-D12-E12 | G12: =IF(C12=0,"",E12/C12) | H12: =IF(C12+D12+E12=0,"",SUM($F$11:F12))
B13: มี.ค. | C13: =SUMIFS(Transaction!$E:$E,Transaction!$C:$C,"รายรับ",Transaction!$B:$B,">="&DATE($P$3,MATCH($B13,Setup!$J$6:$J$17,0),1),Transaction!$B:$B,"<"&DATE($P$3,MATCH($B13,Setup!$J$6:$J$17,0)+1,1)) | D13: =SUMIFS(Transaction!$E:$E,Transaction!$C:$C,"รายจ่าย",Transaction!$B:$B,">="&DATE($P$3,MATCH($B13,Setup!$J$6:$J$17,0),1),Transaction!$B:$B,"<"&DATE($P$3,MATCH($B13,Setup!$J$6:$J$17,0)+1,1)) | E13: =SUMIFS(Transaction!$E:$E,Transaction!$C:$C,"เงินออม",Transaction!$B:$B,">="&DATE($P$3,MATCH($B13,Setup!$J$6:$J$17,0),1),Transaction!$B:$B,"<"&DATE($P$3,MATCH($B13,Setup!$J$6:$J$17,0)+1,1)) | F13: =C13-D13-E13 | G13: =IF(C13=0,"",E13/C13) | H13: =IF(C13+D13+E13=0,"",SUM($F$11:F13))
B14: เม.ย. | C14: =SUMIFS(Transaction!$E:$E,Transaction!$C:$C,"รายรับ",Transaction!$B:$B,">="&DATE($P$3,MATCH($B14,Setup!$J$6:$J$17,0),1),Transaction!$B:$B,"<"&DATE($P$3,MATCH($B14,Setup!$J$6:$J$17,0)+1,1)) | D14: =SUMIFS(Transaction!$E:$E,Transaction!$C:$C,"รายจ่าย",Transaction!$B:$B,">="&DATE($P$3,MATCH($B14,Setup!$J$6:$J$17,0),1),Transaction!$B:$B,"<"&DATE($P$3,MATCH($B14,Setup!$J$6:$J$17,0)+1,1)) | E14: =SUMIFS(Transaction!$E:$E,Transaction!$C:$C,"เงินออม",Transaction!$B:$B,">="&DATE($P$3,MATCH($B14,Setup!$J$6:$J$17,0),1),Transaction!$B:$B,"<"&DATE($P$3,MATCH($B14,Setup!$J$6:$J$17,0)+1,1)) | F14: =C14-D14-E14 | G14: =IF(C14=0,"",E14/C14) | H14: =IF(C14+D14+E14=0,"",SUM($F$11:F14))
B15: พ.ค. | C15: =SUMIFS(Transaction!$E:$E,Transaction!$C:$C,"รายรับ",Transaction!$B:$B,">="&DATE($P$3,MATCH($B15,Setup!$J$6:$J$17,0),1),Transaction!$B:$B,"<"&DATE($P$3,MATCH($B15,Setup!$J$6:$J$17,0)+1,1)) | D15: =SUMIFS(Transaction!$E:$E,Transaction!$C:$C,"รายจ่าย",Transaction!$B:$B,">="&DATE($P$3,MATCH($B15,Setup!$J$6:$J$17,0),1),Transaction!$B:$B,"<"&DATE($P$3,MATCH($B15,Setup!$J$6:$J$17,0)+1,1)) | E15: =SUMIFS(Transaction!$E:$E,Transaction!$C:$C,"เงินออม",Transaction!$B:$B,">="&DATE($P$3,MATCH($B15,Setup!$J$6:$J$17,0),1),Transaction!$B:$B,"<"&DATE($P$3,MATCH($B15,Setup!$J$6:$J$17,0)+1,1)) | F15: =C15-D15-E15 | G15: =IF(C15=0,"",E15/C15) | H15: =IF(C15+D15+E15=0,"",SUM($F$11:F15))
B16: มิ.ย. | C16: =SUMIFS(Transaction!$E:$E,Transaction!$C:$C,"รายรับ",Transaction!$B:$B,">="&DATE($P$3,MATCH($B16,Setup!$J$6:$J$17,0),1),Transaction!$B:$B,"<"&DATE($P$3,MATCH($B16,Setup!$J$6:$J$17,0)+1,1)) | D16: =SUMIFS(Transaction!$E:$E,Transaction!$C:$C,"รายจ่าย",Transaction!$B:$B,">="&DATE($P$3,MATCH($B16,Setup!$J$6:$J$17,0),1),Transaction!$B:$B,"<"&DATE($P$3,MATCH($B16,Setup!$J$6:$J$17,0)+1,1)) | E16: =SUMIFS(Transaction!$E:$E,Transaction!$C:$C,"เงินออม",Transaction!$B:$B,">="&DATE($P$3,MATCH($B16,Setup!$J$6:$J$17,0),1),Transaction!$B:$B,"<"&DATE($P$3,MATCH($B16,Setup!$J$6:$J$17,0)+1,1)) | F16: =C16-D16-E16 | G16: =IF(C16=0,"",E16/C16) | H16: =IF(C16+D16+E16=0,"",SUM($F$11:F16))
B17: ก.ค. | C17: =SUMIFS(Transaction!$E:$E,Transaction!$C:$C,"รายรับ",Transaction!$B:$B,">="&DATE($P$3,MATCH($B17,Setup!$J$6:$J$17,0),1),Transaction!$B:$B,"<"&DATE($P$3,MATCH($B17,Setup!$J$6:$J$17,0)+1,1)) | D17: =SUMIFS(Transaction!$E:$E,Transaction!$C:$C,"รายจ่าย",Transaction!$B:$B,">="&DATE($P$3,MATCH($B17,Setup!$J$6:$J$17,0),1),Transaction!$B:$B,"<"&DATE($P$3,MATCH($B17,Setup!$J$6:$J$17,0)+1,1)) | E17: =SUMIFS(Transaction!$E:$E,Transaction!$C:$C,"เงินออม",Transaction!$B:$B,">="&DATE($P$3,MATCH($B17,Setup!$J$6:$J$17,0),1),Transaction!$B:$B,"<"&DATE($P$3,MATCH($B17,Setup!$J$6:$J$17,0)+1,1)) | F17: =C17-D17-E17 | G17: =IF(C17=0,"",E17/C17) | H17: =IF(C17+D17+E17=0,"",SUM($F$11:F17))
B18: ส.ค. | C18: =SUMIFS(Transaction!$E:$E,Transaction!$C:$C,"รายรับ",Transaction!$B:$B,">="&DATE($P$3,MATCH($B18,Setup!$J$6:$J$17,0),1),Transaction!$B:$B,"<"&DATE($P$3,MATCH($B18,Setup!$J$6:$J$17,0)+1,1)) | D18: =SUMIFS(Transaction!$E:$E,Transaction!$C:$C,"รายจ่าย",Transaction!$B:$B,">="&DATE($P$3,MATCH($B18,Setup!$J$6:$J$17,0),1),Transaction!$B:$B,"<"&DATE($P$3,MATCH($B18,Setup!$J$6:$J$17,0)+1,1)) | E18: =SUMIFS(Transaction!$E:$E,Transaction!$C:$C,"เงินออม",Transaction!$B:$B,">="&DATE($P$3,MATCH($B18,Setup!$J$6:$J$17,0),1),Transaction!$B:$B,"<"&DATE($P$3,MATCH($B18,Setup!$J$6:$J$17,0)+1,1)) | F18: =C18-D18-E18 | G18: =IF(C18=0,"",E18/C18) | H18: =IF(C18+D18+E18=0,"",SUM($F$11:F18))
B19: ก.ย. | C19: =SUMIFS(Transaction!$E:$E,Transaction!$C:$C,"รายรับ",Transaction!$B:$B,">="&DATE($P$3,MATCH($B19,Setup!$J$6:$J$17,0),1),Transaction!$B:$B,"<"&DATE($P$3,MATCH($B19,Setup!$J$6:$J$17,0)+1,1)) | D19: =SUMIFS(Transaction!$E:$E,Transaction!$C:$C,"รายจ่าย",Transaction!$B:$B,">="&DATE($P$3,MATCH($B19,Setup!$J$6:$J$17,0),1),Transaction!$B:$B,"<"&DATE($P$3,MATCH($B19,Setup!$J$6:$J$17,0)+1,1)) | E19: =SUMIFS(Transaction!$E:$E,Transaction!$C:$C,"เงินออม",Transaction!$B:$B,">="&DATE($P$3,MATCH($B19,Setup!$J$6:$J$17,0),1),Transaction!$B:$B,"<"&DATE($P$3,MATCH($B19,Setup!$J$6:$J$17,0)+1,1)) | F19: =C19-D19-E19 | G19: =IF(C19=0,"",E19/C19) | H19: =IF(C19+D19+E19=0,"",SUM($F$11:F19))
B20: ต.ค. | C20: =SUMIFS(Transaction!$E:$E,Transaction!$C:$C,"รายรับ",Transaction!$B:$B,">="&DATE($P$3,MATCH($B20,Setup!$J$6:$J$17,0),1),Transaction!$B:$B,"<"&DATE($P$3,MATCH($B20,Setup!$J$6:$J$17,0)+1,1)) | D20: =SUMIFS(Transaction!$E:$E,Transaction!$C:$C,"รายจ่าย",Transaction!$B:$B,">="&DATE($P$3,MATCH($B20,Setup!$J$6:$J$17,0),1),Transaction!$B:$B,"<"&DATE($P$3,MATCH($B20,Setup!$J$6:$J$17,0)+1,1)) | E20: =SUMIFS(Transaction!$E:$E,Transaction!$C:$C,"เงินออม",Transaction!$B:$B,">="&DATE($P$3,MATCH($B20,Setup!$J$6:$J$17,0),1),Transaction!$B:$B,"<"&DATE($P$3,MATCH($B20,Setup!$J$6:$J$17,0)+1,1)) | F20: =C20-D20-E20 | G20: =IF(C20=0,"",E20/C20) | H20: =IF(C20+D20+E20=0,"",SUM($F$11:F20))
B21: พ.ย. | C21: =SUMIFS(Transaction!$E:$E,Transaction!$C:$C,"รายรับ",Transaction!$B:$B,">="&DATE($P$3,MATCH($B21,Setup!$J$6:$J$17,0),1),Transaction!$B:$B,"<"&DATE($P$3,MATCH($B21,Setup!$J$6:$J$17,0)+1,1)) | D21: =SUMIFS(Transaction!$E:$E,Transaction!$C:$C,"รายจ่าย",Transaction!$B:$B,">="&DATE($P$3,MATCH($B21,Setup!$J$6:$J$17,0),1),Transaction!$B:$B,"<"&DATE($P$3,MATCH($B21,Setup!$J$6:$J$17,0)+1,1)) | E21: =SUMIFS(Transaction!$E:$E,Transaction!$C:$C,"เงินออม",Transaction!$B:$B,">="&DATE($P$3,MATCH($B21,Setup!$J$6:$J$17,0),1),Transaction!$B:$B,"<"&DATE($P$3,MATCH($B21,Setup!$J$6:$J$17,0)+1,1)) | F21: =C21-D21-E21 | G21: =IF(C21=0,"",E21/C21) | H21: =IF(C21+D21+E21=0,"",SUM($F$11:F21))
B22: ธ.ค. | C22: =SUMIFS(Transaction!$E:$E,Transaction!$C:$C,"รายรับ",Transaction!$B:$B,">="&DATE($P$3,MATCH($B22,Setup!$J$6:$J$17,0),1),Transaction!$B:$B,"<"&DATE($P$3,MATCH($B22,Setup!$J$6:$J$17,0)+1,1)) | D22: =SUMIFS(Transaction!$E:$E,Transaction!$C:$C,"รายจ่าย",Transaction!$B:$B,">="&DATE($P$3,MATCH($B22,Setup!$J$6:$J$17,0),1),Transaction!$B:$B,"<"&DATE($P$3,MATCH($B22,Setup!$J$6:$J$17,0)+1,1)) | E22: =SUMIFS(Transaction!$E:$E,Transaction!$C:$C,"เงินออม",Transaction!$B:$B,">="&DATE($P$3,MATCH($B22,Setup!$J$6:$J$17,0),1),Transaction!$B:$B,"<"&DATE($P$3,MATCH($B22,Setup!$J$6:$J$17,0)+1,1)) | F22: =C22-D22-E22 | G22: =IF(C22=0,"",E22/C22) | H22: =IF(C22+D22+E22=0,"",SUM($F$11:F22))
B23: รวมทั้งปี | C23: =SUM(C11:C22) | D23: =SUM(D11:D22) | E23: =SUM(E11:E22) | F23: =SUM(F11:F22) | G23: =IF(C23=0,"",E23/C23)
B24: เฉลี่ย/เดือน | C24: =IF(N($P$6)=0,0,C23/$P$6) | D24: =IF(N($P$6)=0,0,D23/$P$6) | E24: =IF(N($P$6)=0,0,E23/$P$6) | F24: =IF(N($P$6)=0,0,F23/$P$6) | G24: =IF(C24=0,"",E24/C24)
B25: * คงเหลือ = รายรับ − รายจ่าย − เงินออม · ค่าเฉลี่ยคิดจากเดือนที่มีการบันทึกข้อมูล
B27: 🍩 สัดส่วนตามหมวดหมู่ & Top 10 (ทั้งปี) | S27: ⚙️ ข้อมูลประกอบกราฟ (ระบบคำนวณ — ไม่ต้องแก้ไข)
S28: กราฟ: รายรับ | T28: จำนวนเงิน | V28: กราฟ: รายจ่าย | W28: จำนวนเงิน | Y28: กราฟ: เงินออม | Z28: จำนวนเงิน
S29: =IFERROR(INDEX($B$63:$B$77,MATCH(1,$Q$63:$Q$77,0)),"") | T29: =IFERROR(INDEX($O$63:$O$77,MATCH(1,$Q$63:$Q$77,0)),"") | V29: =IFERROR(INDEX($B$81:$B$105,MATCH(1,$Q$81:$Q$105,0)),"") | W29: =IFERROR(INDEX($O$81:$O$105,MATCH(1,$Q$81:$Q$105,0)),"") | Y29: =IFERROR(INDEX($B$109:$B$123,MATCH(1,$Q$109:$Q$123,0)),"") | Z29: =IFERROR(INDEX($O$109:$O$123,MATCH(1,$Q$109:$Q$123,0)),"")
S30: =IFERROR(INDEX($B$63:$B$77,MATCH(2,$Q$63:$Q$77,0)),"") | T30: =IFERROR(INDEX($O$63:$O$77,MATCH(2,$Q$63:$Q$77,0)),"") | V30: =IFERROR(INDEX($B$81:$B$105,MATCH(2,$Q$81:$Q$105,0)),"") | W30: =IFERROR(INDEX($O$81:$O$105,MATCH(2,$Q$81:$Q$105,0)),"") | Y30: =IFERROR(INDEX($B$109:$B$123,MATCH(2,$Q$109:$Q$123,0)),"") | Z30: =IFERROR(INDEX($O$109:$O$123,MATCH(2,$Q$109:$Q$123,0)),"")
S31: =IFERROR(INDEX($B$63:$B$77,MATCH(3,$Q$63:$Q$77,0)),"") | T31: =IFERROR(INDEX($O$63:$O$77,MATCH(3,$Q$63:$Q$77,0)),"") | V31: =IFERROR(INDEX($B$81:$B$105,MATCH(3,$Q$81:$Q$105,0)),"") | W31: =IFERROR(INDEX($O$81:$O$105,MATCH(3,$Q$81:$Q$105,0)),"") | Y31: =IFERROR(INDEX($B$109:$B$123,MATCH(3,$Q$109:$Q$123,0)),"") | Z31: =IFERROR(INDEX($O$109:$O$123,MATCH(3,$Q$109:$Q$123,0)),"")
S32: =IFERROR(INDEX($B$63:$B$77,MATCH(4,$Q$63:$Q$77,0)),"") | T32: =IFERROR(INDEX($O$63:$O$77,MATCH(4,$Q$63:$Q$77,0)),"") | V32: =IFERROR(INDEX($B$81:$B$105,MATCH(4,$Q$81:$Q$105,0)),"") | W32: =IFERROR(INDEX($O$81:$O$105,MATCH(4,$Q$81:$Q$105,0)),"") | Y32: =IFERROR(INDEX($B$109:$B$123,MATCH(4,$Q$109:$Q$123,0)),"") | Z32: =IFERROR(INDEX($O$109:$O$123,MATCH(4,$Q$109:$Q$123,0)),"")
S33: =IFERROR(INDEX($B$63:$B$77,MATCH(5,$Q$63:$Q$77,0)),"") | T33: =IFERROR(INDEX($O$63:$O$77,MATCH(5,$Q$63:$Q$77,0)),"") | V33: =IFERROR(INDEX($B$81:$B$105,MATCH(5,$Q$81:$Q$105,0)),"") | W33: =IFERROR(INDEX($O$81:$O$105,MATCH(5,$Q$81:$Q$105,0)),"") | Y33: =IFERROR(INDEX($B$109:$B$123,MATCH(5,$Q$109:$Q$123,0)),"") | Z33: =IFERROR(INDEX($O$109:$O$123,MATCH(5,$Q$109:$Q$123,0)),"")
S34: =IFERROR(INDEX($B$63:$B$77,MATCH(6,$Q$63:$Q$77,0)),"") | T34: =IFERROR(INDEX($O$63:$O$77,MATCH(6,$Q$63:$Q$77,0)),"") | V34: =IFERROR(INDEX($B$81:$B$105,MATCH(6,$Q$81:$Q$105,0)),"") | W34: =IFERROR(INDEX($O$81:$O$105,MATCH(6,$Q$81:$Q$105,0)),"") | Y34: =IFERROR(INDEX($B$109:$B$123,MATCH(6,$Q$109:$Q$123,0)),"") | Z34: =IFERROR(INDEX($O$109:$O$123,MATCH(6,$Q$109:$Q$123,0)),"")
S35: =IFERROR(INDEX($B$63:$B$77,MATCH(7,$Q$63:$Q$77,0)),"") | T35: =IFERROR(INDEX($O$63:$O$77,MATCH(7,$Q$63:$Q$77,0)),"") | V35: =IFERROR(INDEX($B$81:$B$105,MATCH(7,$Q$81:$Q$105,0)),"") | W35: =IFERROR(INDEX($O$81:$O$105,MATCH(7,$Q$81:$Q$105,0)),"") | Y35: =IFERROR(INDEX($B$109:$B$123,MATCH(7,$Q$109:$Q$123,0)),"") | Z35: =IFERROR(INDEX($O$109:$O$123,MATCH(7,$Q$109:$Q$123,0)),"")
S36: อื่นๆ | T36: =IF(MAX(0,$O$78-SUM(T29:T35))=0,"",MAX(0,$O$78-SUM(T29:T35))) | V36: อื่นๆ | W36: =IF(MAX(0,$O$106-SUM(W29:W35))=0,"",MAX(0,$O$106-SUM(W29:W35))) | Y36: อื่นๆ | Z36: =IF(MAX(0,$O$124-SUM(Z29:Z35))=0,"",MAX(0,$O$124-SUM(Z29:Z35)))
B45: 🏆 Top 10 รายรับ | G45: 🏆 Top 10 รายจ่าย | M45: 🏆 Top 10 เงินออม
B46: หมวดหมู่ | C46: จำนวนเงิน | D46: % | E46: สัดส่วน | G46: หมวดหมู่ | I46: จำนวนเงิน | J46: % | K46: สัดส่วน | M46: หมวดหมู่ | O46: จำนวนเงิน | P46: % | Q46: สัดส่วน
B47: =IFERROR("1. "&INDEX($B$63:$B$77,MATCH(1,$Q$63:$Q$77,0)),"") | C47: =IFERROR(INDEX($O$63:$O$77,MATCH(1,$Q$63:$Q$77,0)),"") | D47: =IF(OR(C47="",N(C$58)=0),"",C47/C$58) | E47: =IF(C47="","",REPT("█",MAX(1,ROUND(C47/MAX($C$47:$C$56)*10,0)))) | G47: =IFERROR("1. "&INDEX($B$81:$B$105,MATCH(1,$Q$81:$Q$105,0)),"") | I47: =IFERROR(INDEX($O$81:$O$105,MATCH(1,$Q$81:$Q$105,0)),"") | J47: =IF(OR(I47="",N(I$58)=0),"",I47/I$58) | K47: =IF(I47="","",REPT("█",MAX(1,ROUND(I47/MAX($I$47:$I$56)*10,0)))) | M47: =IFERROR("1. "&INDEX($B$109:$B$123,MATCH(1,$Q$109:$Q$123,0)),"") | O47: =IFERROR(INDEX($O$109:$O$123,MATCH(1,$Q$109:$Q$123,0)),"") | P47: =IF(OR(O47="",N(O$58)=0),"",O47/O$58) | Q47: =IF(O47="","",REPT("█",MAX(1,ROUND(O47/MAX($O$47:$O$56)*10,0))))
B48: =IFERROR("2. "&INDEX($B$63:$B$77,MATCH(2,$Q$63:$Q$77,0)),"") | C48: =IFERROR(INDEX($O$63:$O$77,MATCH(2,$Q$63:$Q$77,0)),"") | D48: =IF(OR(C48="",N(C$58)=0),"",C48/C$58) | E48: =IF(C48="","",REPT("█",MAX(1,ROUND(C48/MAX($C$47:$C$56)*10,0)))) | G48: =IFERROR("2. "&INDEX($B$81:$B$105,MATCH(2,$Q$81:$Q$105,0)),"") | I48: =IFERROR(INDEX($O$81:$O$105,MATCH(2,$Q$81:$Q$105,0)),"") | J48: =IF(OR(I48="",N(I$58)=0),"",I48/I$58) | K48: =IF(I48="","",REPT("█",MAX(1,ROUND(I48/MAX($I$47:$I$56)*10,0)))) | M48: =IFERROR("2. "&INDEX($B$109:$B$123,MATCH(2,$Q$109:$Q$123,0)),"") | O48: =IFERROR(INDEX($O$109:$O$123,MATCH(2,$Q$109:$Q$123,0)),"") | P48: =IF(OR(O48="",N(O$58)=0),"",O48/O$58) | Q48: =IF(O48="","",REPT("█",MAX(1,ROUND(O48/MAX($O$47:$O$56)*10,0))))
B49: =IFERROR("3. "&INDEX($B$63:$B$77,MATCH(3,$Q$63:$Q$77,0)),"") | C49: =IFERROR(INDEX($O$63:$O$77,MATCH(3,$Q$63:$Q$77,0)),"") | D49: =IF(OR(C49="",N(C$58)=0),"",C49/C$58) | E49: =IF(C49="","",REPT("█",MAX(1,ROUND(C49/MAX($C$47:$C$56)*10,0)))) | G49: =IFERROR("3. "&INDEX($B$81:$B$105,MATCH(3,$Q$81:$Q$105,0)),"") | I49: =IFERROR(INDEX($O$81:$O$105,MATCH(3,$Q$81:$Q$105,0)),"") | J49: =IF(OR(I49="",N(I$58)=0),"",I49/I$58) | K49: =IF(I49="","",REPT("█",MAX(1,ROUND(I49/MAX($I$47:$I$56)*10,0)))) | M49: =IFERROR("3. "&INDEX($B$109:$B$123,MATCH(3,$Q$109:$Q$123,0)),"") | O49: =IFERROR(INDEX($O$109:$O$123,MATCH(3,$Q$109:$Q$123,0)),"") | P49: =IF(OR(O49="",N(O$58)=0),"",O49/O$58) | Q49: =IF(O49="","",REPT("█",MAX(1,ROUND(O49/MAX($O$47:$O$56)*10,0))))
B50: =IFERROR("4. "&INDEX($B$63:$B$77,MATCH(4,$Q$63:$Q$77,0)),"") | C50: =IFERROR(INDEX($O$63:$O$77,MATCH(4,$Q$63:$Q$77,0)),"") | D50: =IF(OR(C50="",N(C$58)=0),"",C50/C$58) | E50: =IF(C50="","",REPT("█",MAX(1,ROUND(C50/MAX($C$47:$C$56)*10,0)))) | G50: =IFERROR("4. "&INDEX($B$81:$B$105,MATCH(4,$Q$81:$Q$105,0)),"") | I50: =IFERROR(INDEX($O$81:$O$105,MATCH(4,$Q$81:$Q$105,0)),"") | J50: =IF(OR(I50="",N(I$58)=0),"",I50/I$58) | K50: =IF(I50="","",REPT("█",MAX(1,ROUND(I50/MAX($I$47:$I$56)*10,0)))) | M50: =IFERROR("4. "&INDEX($B$109:$B$123,MATCH(4,$Q$109:$Q$123,0)),"") | O50: =IFERROR(INDEX($O$109:$O$123,MATCH(4,$Q$109:$Q$123,0)),"") | P50: =IF(OR(O50="",N(O$58)=0),"",O50/O$58) | Q50: =IF(O50="","",REPT("█",MAX(1,ROUND(O50/MAX($O$47:$O$56)*10,0))))
B51: =IFERROR("5. "&INDEX($B$63:$B$77,MATCH(5,$Q$63:$Q$77,0)),"") | C51: =IFERROR(INDEX($O$63:$O$77,MATCH(5,$Q$63:$Q$77,0)),"") | D51: =IF(OR(C51="",N(C$58)=0),"",C51/C$58) | E51: =IF(C51="","",REPT("█",MAX(1,ROUND(C51/MAX($C$47:$C$56)*10,0)))) | G51: =IFERROR("5. "&INDEX($B$81:$B$105,MATCH(5,$Q$81:$Q$105,0)),"") | I51: =IFERROR(INDEX($O$81:$O$105,MATCH(5,$Q$81:$Q$105,0)),"") | J51: =IF(OR(I51="",N(I$58)=0),"",I51/I$58) | K51: =IF(I51="","",REPT("█",MAX(1,ROUND(I51/MAX($I$47:$I$56)*10,0)))) | M51: =IFERROR("5. "&INDEX($B$109:$B$123,MATCH(5,$Q$109:$Q$123,0)),"") | O51: =IFERROR(INDEX($O$109:$O$123,MATCH(5,$Q$109:$Q$123,0)),"") | P51: =IF(OR(O51="",N(O$58)=0),"",O51/O$58) | Q51: =IF(O51="","",REPT("█",MAX(1,ROUND(O51/MAX($O$47:$O$56)*10,0))))
B52: =IFERROR("6. "&INDEX($B$63:$B$77,MATCH(6,$Q$63:$Q$77,0)),"") | C52: =IFERROR(INDEX($O$63:$O$77,MATCH(6,$Q$63:$Q$77,0)),"") | D52: =IF(OR(C52="",N(C$58)=0),"",C52/C$58) | E52: =IF(C52="","",REPT("█",MAX(1,ROUND(C52/MAX($C$47:$C$56)*10,0)))) | G52: =IFERROR("6. "&INDEX($B$81:$B$105,MATCH(6,$Q$81:$Q$105,0)),"") | I52: =IFERROR(INDEX($O$81:$O$105,MATCH(6,$Q$81:$Q$105,0)),"") | J52: =IF(OR(I52="",N(I$58)=0),"",I52/I$58) | K52: =IF(I52="","",REPT("█",MAX(1,ROUND(I52/MAX($I$47:$I$56)*10,0)))) | M52: =IFERROR("6. "&INDEX($B$109:$B$123,MATCH(6,$Q$109:$Q$123,0)),"") | O52: =IFERROR(INDEX($O$109:$O$123,MATCH(6,$Q$109:$Q$123,0)),"") | P52: =IF(OR(O52="",N(O$58)=0),"",O52/O$58) | Q52: =IF(O52="","",REPT("█",MAX(1,ROUND(O52/MAX($O$47:$O$56)*10,0))))
...

Sheet Monthly Overview
B2: 📈 Monthly Overview — สรุปรายเดือน | S2: ⚙️ ส่วนคำนวณของระบบ (ไม่ต้องแก้ไข)
B3: ="ข้อมูลเดือน "&$O$3&" "&$L$3&" (พ.ศ. "&($L$3+543)&") · เปรียบเทียบกับเดือนก่อนอัตโนมัติ" | K3: ปี ค.ศ. ▸ | L3: 2026 | M3: เดือน ▸ | O3: กันยายน | S3: เดือนที่ (ตัวเลข) | T3: =MATCH($O$3,Setup!$I$6:$I$17,0)
S4: วันแรกของเดือน | T4: =DATE($L$3,$T$3,1)
B5: 💰 รายรับ | D5: 💸 รายจ่าย | G5: 🏦 เงินออม | J5: 💵 คงเหลือ (Cash Flow) | M5: 📈 อัตราการออม | P5: 🧾 จำนวนรายการ | S5: วันแรกเดือนถัดไป | T5: =DATE($L$3,$T$3+1,1)
B6: =$C$11 | D6: =$C$12 | G6: =$C$13 | J6: =$C$14 | M6: =IF($C$11=0,0,$C$13/$C$11) | P6: =COUNTIFS(Transaction!$B:$B,">="&$T$4,Transaction!$B:$B,"<"&$T$5) | S6: วันแรกเดือนก่อน | T6: =DATE($L$3,$T$3-1,1)
B7: =IF($D$11=0,"ไม่มีข้อมูลเดือนก่อน",IF($C$11>=$D$11,"▲ ","▼ ")&TEXT(ABS(($C$11-$D$11)/$D$11),"0.0%")&" จากเดือนก่อน") | D7: =IF($D$12=0,"ไม่มีข้อมูลเดือนก่อน",IF($C$12>=$D$12,"▲ ","▼ ")&TEXT(ABS(($C$12-$D$12)/$D$12),"0.0%")&" จากเดือนก่อน") | G7: =IF($D$13=0,"ไม่มีข้อมูลเดือนก่อน",IF($C$13>=$D$13,"▲ ","▼ ")&TEXT(ABS(($C$13-$D$13)/$D$13),"0.0%")&" จากเดือนก่อน") | J7: =IF($C$11=0,"","คิดเป็น "&TEXT($C$14/$C$11,"0%")&" ของรายรับ") | M7: ="เดือนก่อน "&TEXT(IF($D$11=0,0,$D$13/$D$11),"0.0%") | P7: บันทึกในเดือนนี้ | S7: จำนวนวันในเดือน | T7: =DAY($T$5-1)
B9: 📊 ภาพรวมเดือนนี้ เทียบกับเดือนก่อน
B10: รายการ | C10: เดือนนี้ | D10: เดือนก่อน | E10: เปลี่ยนแปลง | F10: % | S10: หมวดรายรับ | T10: ยอดเดือนนี้ | U10: อันดับ | W10: หมวดรายจ่าย | X10: ยอดเดือนนี้ | Y10: อันดับ | AA10: หมวดเงินออม | AB10: ยอดเดือนนี้ | AC10: อันดับ
B11: รายรับ | C11: =SUMIFS(Transaction!$E:$E,Transaction!$C:$C,"รายรับ",Transaction!$B:$B,">="&$T$4,Transaction!$B:$B,"<"&$T$5) | D11: =SUMIFS(Transaction!$E:$E,Transaction!$C:$C,"รายรับ",Transaction!$B:$B,">="&$T$6,Transaction!$B:$B,"<"&$T$4) | E11: =C11-D11 | F11: =IF(D11=0,"",(C11-D11)/ABS(D11)) | S11: =IF(Setup!$B$6="","",Setup!$B$6) | T11: =IF(S11="","",SUMIFS(Transaction!$E:$E,Transaction!$C:$C,"รายรับ",Transaction!$D:$D,S11,Transaction!$B:$B,">="&$T$4,Transaction!$B:$B,"<"&$T$5)) | U11: =IF(OR(S11="",N(T11)<=0),"",COUNTIF($T$11:$T$25,">"&T11)+COUNTIF($T$11:T11,T11)) | W11: =IF(Setup!$D$6="","",Setup!$D$6) | X11: =IF(W11="","",SUMIFS(Transaction!$E:$E,Transaction!$C:$C,"รายจ่าย",Transaction!$D:$D,W11,Transaction!$B:$B,">="&$T$4,Transaction!$B:$B,"<"&$T$5)) | Y11: =IF(OR(W11="",N(X11)<=0),"",COUNTIF($X$11:$X$35,">"&X11)+COUNTIF($X$11:X11,X11)) | AA11: =IF(Setup!$F$6="","",Setup!$F$6) | AB11: =IF(AA11="","",SUMIFS(Transaction!$E:$E,Transaction!$C:$C,"เงินออม",Transaction!$D:$D,AA11,Transaction!$B:$B,">="&$T$4,Transaction!$B:$B,"<"&$T$5)) | AC11: =IF(OR(AA11="",N(AB11)<=0),"",COUNTIF($AB$11:$AB$25,">"&AB11)+COUNTIF($AB$11:AB11,AB11))
B12: รายจ่าย | C12: =SUMIFS(Transaction!$E:$E,Transaction!$C:$C,"รายจ่าย",Transaction!$B:$B,">="&$T$4,Transaction!$B:$B,"<"&$T$5) | D12: =SUMIFS(Transaction!$E:$E,Transaction!$C:$C,"รายจ่าย",Transaction!$B:$B,">="&$T$6,Transaction!$B:$B,"<"&$T$4) | E12: =C12-D12 | F12: =IF(D12=0,"",(C12-D12)/ABS(D12)) | S12: =IF(Setup!$B$7="","",Setup!$B$7) | T12: =IF(S12="","",SUMIFS(Transaction!$E:$E,Transaction!$C:$C,"รายรับ",Transaction!$D:$D,S12,Transaction!$B:$B,">="&$T$4,Transaction!$B:$B,"<"&$T$5)) | U12: =IF(OR(S12="",N(T12)<=0),"",COUNTIF($T$11:$T$25,">"&T12)+COUNTIF($T$11:T12,T12)) | W12: =IF(Setup!$D$7="","",Setup!$D$7) | X12: =IF(W12="","",SUMIFS(Transaction!$E:$E,Transaction!$C:$C,"รายจ่าย",Transaction!$D:$D,W12,Transaction!$B:$B,">="&$T$4,Transaction!$B:$B,"<"&$T$5)) | Y12: =IF(OR(W12="",N(X12)<=0),"",COUNTIF($X$11:$X$35,">"&X12)+COUNTIF($X$11:X12,X12)) | AA12: =IF(Setup!$F$7="","",Setup!$F$7) | AB12: =IF(AA12="","",SUMIFS(Transaction!$E:$E,Transaction!$C:$C,"เงินออม",Transaction!$D:$D,AA12,Transaction!$B:$B,">="&$T$4,Transaction!$B:$B,"<"&$T$5)) | AC12: =IF(OR(AA12="",N(AB12)<=0),"",COUNTIF($AB$11:$AB$25,">"&AB12)+COUNTIF($AB$11:AB12,AB12))
B13: เงินออม | C13: =SUMIFS(Transaction!$E:$E,Transaction!$C:$C,"เงินออม",Transaction!$B:$B,">="&$T$4,Transaction!$B:$B,"<"&$T$5) | D13: =SUMIFS(Transaction!$E:$E,Transaction!$C:$C,"เงินออม",Transaction!$B:$B,">="&$T$6,Transaction!$B:$B,"<"&$T$4) | E13: =C13-D13 | F13: =IF(D13=0,"",(C13-D13)/ABS(D13)) | S13: =IF(Setup!$B$8="","",Setup!$B$8) | T13: =IF(S13="","",SUMIFS(Transaction!$E:$E,Transaction!$C:$C,"รายรับ",Transaction!$D:$D,S13,Transaction!$B:$B,">="&$T$4,Transaction!$B:$B,"<"&$T$5)) | U13: =IF(OR(S13="",N(T13)<=0),"",COUNTIF($T$11:$T$25,">"&T13)+COUNTIF($T$11:T13,T13)) | W13: =IF(Setup!$D$8="","",Setup!$D$8) | X13: =IF(W13="","",SUMIFS(Transaction!$E:$E,Transaction!$C:$C,"รายจ่าย",Transaction!$D:$D,W13,Transaction!$B:$B,">="&$T$4,Transaction!$B:$B,"<"&$T$5)) | Y13: =IF(OR(W13="",N(X13)<=0),"",COUNTIF($X$11:$X$35,">"&X13)+COUNTIF($X$11:X13,X13)) | AA13: =IF(Setup!$F$8="","",Setup!$F$8) | AB13: =IF(AA13="","",SUMIFS(Transaction!$E:$E,Transaction!$C:$C,"เงินออม",Transaction!$D:$D,AA13,Transaction!$B:$B,">="&$T$4,Transaction!$B:$B,"<"&$T$5)) | AC13: =IF(OR(AA13="",N(AB13)<=0),"",COUNTIF($AB$11:$AB$25,">"&AB13)+COUNTIF($AB$11:AB13,AB13))
B14: คงเหลือ | C14: =C11-C12-C13 | D14: =D11-D12-D13 | E14: =C14-D14 | F14: =IF(D14=0,"",(C14-D14)/ABS(D14)) | S14: =IF(Setup!$B$9="","",Setup!$B$9) | T14: =IF(S14="","",SUMIFS(Transaction!$E:$E,Transaction!$C:$C,"รายรับ",Transaction!$D:$D,S14,Transaction!$B:$B,">="&$T$4,Transaction!$B:$B,"<"&$T$5)) | U14: =IF(OR(S14="",N(T14)<=0),"",COUNTIF($T$11:$T$25,">"&T14)+COUNTIF($T$11:T14,T14)) | W14: =IF(Setup!$D$9="","",Setup!$D$9) | X14: =IF(W14="","",SUMIFS(Transaction!$E:$E,Transaction!$C:$C,"รายจ่าย",Transaction!$D:$D,W14,Transaction!$B:$B,">="&$T$4,Transaction!$B:$B,"<"&$T$5)) | Y14: =IF(OR(W14="",N(X14)<=0),"",COUNTIF($X$11:$X$35,">"&X14)+COUNTIF($X$11:X14,X14)) | AA14: =IF(Setup!$F$9="","",Setup!$F$9) | AB14: =IF(AA14="","",SUMIFS(Transaction!$E:$E,Transaction!$C:$C,"เงินออม",Transaction!$D:$D,AA14,Transaction!$B:$B,">="&$T$4,Transaction!$B:$B,"<"&$T$5)) | AC14: =IF(OR(AA14="",N(AB14)<=0),"",COUNTIF($AB$11:$AB$25,">"&AB14)+COUNTIF($AB$11:AB14,AB14))
S15: =IF(Setup!$B$10="","",Setup!$B$10) | T15: =IF(S15="","",SUMIFS(Transaction!$E:$E,Transaction!$C:$C,"รายรับ",Transaction!$D:$D,S15,Transaction!$B:$B,">="&$T$4,Transaction!$B:$B,"<"&$T$5)) | U15: =IF(OR(S15="",N(T15)<=0),"",COUNTIF($T$11:$T$25,">"&T15)+COUNTIF($T$11:T15,T15)) | W15: =IF(Setup!$D$10="","",Setup!$D$10) | X15: =IF(W15="","",SUMIFS(Transaction!$E:$E,Transaction!$C:$C,"รายจ่าย",Transaction!$D:$D,W15,Transaction!$B:$B,">="&$T$4,Transaction!$B:$B,"<"&$T$5)) | Y15: =IF(OR(W15="",N(X15)<=0),"",COUNTIF($X$11:$X$35,">"&X15)+COUNTIF($X$11:X15,X15)) | AA15: =IF(Setup!$F$10="","",Setup!$F$10) | AB15: =IF(AA15="","",SUMIFS(Transaction!$E:$E,Transaction!$C:$C,"เงินออม",Transaction!$D:$D,AA15,Transaction!$B:$B,">="&$T$4,Transaction!$B:$B,"<"&$T$5)) | AC15: =IF(OR(AA15="",N(AB15)<=0),"",COUNTIF($AB$11:$AB$25,">"&AB15)+COUNTIF($AB$11:AB15,AB15))
B16: การใช้รายรับเดือนนี้ | C16: จำนวนเงิน | D16: สัดส่วน | S16: =IF(Setup!$B$11="","",Setup!$B$11) | T16: =IF(S16="","",SUMIFS(Transaction!$E:$E,Transaction!$C:$C,"รายรับ",Transaction!$D:$D,S16,Transaction!$B:$B,">="&$T$4,Transaction!$B:$B,"<"&$T$5)) | U16: =IF(OR(S16="",N(T16)<=0),"",COUNTIF($T$11:$T$25,">"&T16)+COUNTIF($T$11:T16,T16)) | W16: =IF(Setup!$D$11="","",Setup!$D$11) | X16: =IF(W16="","",SUMIFS(Transaction!$E:$E,Transaction!$C:$C,"รายจ่าย",Transaction!$D:$D,W16,Transaction!$B:$B,">="&$T$4,Transaction!$B:$B,"<"&$T$5)) | Y16: =IF(OR(W16="",N(X16)<=0),"",COUNTIF($X$11:$X$35,">"&X16)+COUNTIF($X$11:X16,X16)) | AA16: =IF(Setup!$F$11="","",Setup!$F$11) | AB16: =IF(AA16="","",SUMIFS(Transaction!$E:$E,Transaction!$C:$C,"เงินออม",Transaction!$D:$D,AA16,Transaction!$B:$B,">="&$T$4,Transaction!$B:$B,"<"&$T$5)) | AC16: =IF(OR(AA16="",N(AB16)<=0),"",COUNTIF($AB$11:$AB$25,">"&AB16)+COUNTIF($AB$11:AB16,AB16))
B17: รายจ่าย | C17: =C12 | D17: =IF($C$11=0,"",C17/$C$11) | S17: =IF(Setup!$B$12="","",Setup!$B$12) | T17: =IF(S17="","",SUMIFS(Transaction!$E:$E,Transaction!$C:$C,"รายรับ",Transaction!$D:$D,S17,Transaction!$B:$B,">="&$T$4,Transaction!$B:$B,"<"&$T$5)) | U17: =IF(OR(S17="",N(T17)<=0),"",COUNTIF($T$11:$T$25,">"&T17)+COUNTIF($T$11:T17,T17)) | W17: =IF(Setup!$D$12="","",Setup!$D$12) | X17: =IF(W17="","",SUMIFS(Transaction!$E:$E,Transaction!$C:$C,"รายจ่าย",Transaction!$D:$D,W17,Transaction!$B:$B,">="&$T$4,Transaction!$B:$B,"<"&$T$5)) | Y17: =IF(OR(W17="",N(X17)<=0),"",COUNTIF($X$11:$X$35,">"&X17)+COUNTIF($X$11:X17,X17)) | AA17: =IF(Setup!$F$12="","",Setup!$F$12) | AB17: =IF(AA17="","",SUMIFS(Transaction!$E:$E,Transaction!$C:$C,"เงินออม",Transaction!$D:$D,AA17,Transaction!$B:$B,">="&$T$4,Transaction!$B:$B,"<"&$T$5)) | AC17: =IF(OR(AA17="",N(AB17)<=0),"",COUNTIF($AB$11:$AB$25,">"&AB17)+COUNTIF($AB$11:AB17,AB17))
B18: เงินออม | C18: =C13 | D18: =IF($C$11=0,"",C18/$C$11) | S18: =IF(Setup!$B$13="","",Setup!$B$13) | T18: =IF(S18="","",SUMIFS(Transaction!$E:$E,Transaction!$C:$C,"รายรับ",Transaction!$D:$D,S18,Transaction!$B:$B,">="&$T$4,Transaction!$B:$B,"<"&$T$5)) | U18: =IF(OR(S18="",N(T18)<=0),"",COUNTIF($T$11:$T$25,">"&T18)+COUNTIF($T$11:T18,T18)) | W18: =IF(Setup!$D$13="","",Setup!$D$13) | X18: =IF(W18="","",SUMIFS(Transaction!$E:$E,Transaction!$C:$C,"รายจ่าย",Transaction!$D:$D,W18,Transaction!$B:$B,">="&$T$4,Transaction!$B:$B,"<"&$T$5)) | Y18: =IF(OR(W18="",N(X18)<=0),"",COUNTIF($X$11:$X$35,">"&X18)+COUNTIF($X$11:X18,X18)) | AA18: =IF(Setup!$F$13="","",Setup!$F$13) | AB18: =IF(AA18="","",SUMIFS(Transaction!$E:$E,Transaction!$C:$C,"เงินออม",Transaction!$D:$D,AA18,Transaction!$B:$B,">="&$T$4,Transaction!$B:$B,"<"&$T$5)) | AC18: =IF(OR(AA18="",N(AB18)<=0),"",COUNTIF($AB$11:$AB$25,">"&AB18)+COUNTIF($AB$11:AB18,AB18))
B19: คงเหลือ | C19: =MAX(0,C14) | D19: =IF($C$11=0,"",C19/$C$11) | S19: =IF(Setup!$B$14="","",Setup!$B$14) | T19: =IF(S19="","",SUMIFS(Transaction!$E:$E,Transaction!$C:$C,"รายรับ",Transaction!$D:$D,S19,Transaction!$B:$B,">="&$T$4,Transaction!$B:$B,"<"&$T$5)) | U19: =IF(OR(S19="",N(T19)<=0),"",COUNTIF($T$11:$T$25,">"&T19)+COUNTIF($T$11:T19,T19)) | W19: =IF(Setup!$D$14="","",Setup!$D$14) | X19: =IF(W19="","",SUMIFS(Transaction!$E:$E,Transaction!$C:$C,"รายจ่าย",Transaction!$D:$D,W19,Transaction!$B:$B,">="&$T$4,Transaction!$B:$B,"<"&$T$5)) | Y19: =IF(OR(W19="",N(X19)<=0),"",COUNTIF($X$11:$X$35,">"&X19)+COUNTIF($X$11:X19,X19)) | AA19: =IF(Setup!$F$14="","",Setup!$F$14) | AB19: =IF(AA19="","",SUMIFS(Transaction!$E:$E,Transaction!$C:$C,"เงินออม",Transaction!$D:$D,AA19,Transaction!$B:$B,">="&$T$4,Transaction!$B:$B,"<"&$T$5)) | AC19: =IF(OR(AA19="",N(AB19)<=0),"",COUNTIF($AB$11:$AB$25,">"&AB19)+COUNTIF($AB$11:AB19,AB19))
B20: =IF(C11+C12+C13=0,"ยังไม่มีข้อมูลในเดือนนี้",IF(C14<0,"⚠ เดือนนี้ใช้เงินเกินรายรับ ฿"&TEXT(-C14,"#,##0"),"✅ เดือนนี้มีเงินเหลือ ฿"&TEXT(C14,"#,##0"))) | S20: =IF(Setup!$B$15="","",Setup!$B$15) | T20: =IF(S20="","",SUMIFS(Transaction!$E:$E,Transaction!$C:$C,"รายรับ",Transaction!$D:$D,S20,Transaction!$B:$B,">="&$T$4,Transaction!$B:$B,"<"&$T$5)) | U20: =IF(OR(S20="",N(T20)<=0),"",COUNTIF($T$11:$T$25,">"&T20)+COUNTIF($T$11:T20,T20)) | W20: =IF(Setup!$D$15="","",Setup!$D$15) | X20: =IF(W20="","",SUMIFS(Transaction!$E:$E,Transaction!$C:$C,"รายจ่าย",Transaction!$D:$D,W20,Transaction!$B:$B,">="&$T$4,Transaction!$B:$B,"<"&$T$5)) | Y20: =IF(OR(W20="",N(X20)<=0),"",COUNTIF($X$11:$X$35,">"&X20)+COUNTIF($X$11:X20,X20)) | AA20: =IF(Setup!$F$15="","",Setup!$F$15) | AB20: =IF(AA20="","",SUMIFS(Transaction!$E:$E,Transaction!$C:$C,"เงินออม",Transaction!$D:$D,AA20,Transaction!$B:$B,">="&$T$4,Transaction!$B:$B,"<"&$T$5)) | AC20: =IF(OR(AA20="",N(AB20)<=0),"",COUNTIF($AB$11:$AB$25,">"&AB20)+COUNTIF($AB$11:AB20,AB20))
S21: =IF(Setup!$B$16="","",Setup!$B$16) | T21: =IF(S21="","",SUMIFS(Transaction!$E:$E,Transaction!$C:$C,"รายรับ",Transaction!$D:$D,S21,Transaction!$B:$B,">="&$T$4,Transaction!$B:$B,"<"&$T$5)) | U21: =IF(OR(S21="",N(T21)<=0),"",COUNTIF($T$11:$T$25,">"&T21)+COUNTIF($T$11:T21,T21)) | W21: =IF(Setup!$D$16="","",Setup!$D$16) | X21: =IF(W21="","",SUMIFS(Transaction!$E:$E,Transaction!$C:$C,"รายจ่าย",Transaction!$D:$D,W21,Transaction!$B:$B,">="&$T$4,Transaction!$B:$B,"<"&$T$5)) | Y21: =IF(OR(W21="",N(X21)<=0),"",COUNTIF($X$11:$X$35,">"&X21)+COUNTIF($X$11:X21,X21)) | AA21: =IF(Setup!$F$16="","",Setup!$F$16) | AB21: =IF(AA21="","",SUMIFS(Transaction!$E:$E,Transaction!$C:$C,"เงินออม",Transaction!$D:$D,AA21,Transaction!$B:$B,">="&$T$4,Transaction!$B:$B,"<"&$T$5)) | AC21: =IF(OR(AA21="",N(AB21)<=0),"",COUNTIF($AB$11:$AB$25,">"&AB21)+COUNTIF($AB$11:AB21,AB21))
B22: 📌 ข้อมูลน่ารู้ | S22: =IF(Setup!$B$17="","",Setup!$B$17) | T22: =IF(S22="","",SUMIFS(Transaction!$E:$E,Transaction!$C:$C,"รายรับ",Transaction!$D:$D,S22,Transaction!$B:$B,">="&$T$4,Transaction!$B:$B,"<"&$T$5)) | U22: =IF(OR(S22="",N(T22)<=0),"",COUNTIF($T$11:$T$25,">"&T22)+COUNTIF($T$11:T22,T22)) | W22: =IF(Setup!$D$17="","",Setup!$D$17) | X22: =IF(W22="","",SUMIFS(Transaction!$E:$E,Transaction!$C:$C,"รายจ่าย",Transaction!$D:$D,W22,Transaction!$B:$B,">="&$T$4,Transaction!$B:$B,"<"&$T$5)) | Y22: =IF(OR(W22="",N(X22)<=0),"",COUNTIF($X$11:$X$35,">"&X22)+COUNTIF($X$11:X22,X22)) | AA22: =IF(Setup!$F$17="","",Setup!$F$17) | AB22: =IF(AA22="","",SUMIFS(Transaction!$E:$E,Transaction!$C:$C,"เงินออม",Transaction!$D:$D,AA22,Transaction!$B:$B,">="&$T$4,Transaction!$B:$B,"<"&$T$5)) | AC22: =IF(OR(AA22="",N(AB22)<=0),"",COUNTIF($AB$11:$AB$25,">"&AB22)+COUNTIF($AB$11:AB22,AB22))
B23: รายจ่ายเฉลี่ยต่อวัน | C23: =IF(N($T$7)=0,0,$C$12/$T$7) | S23: =IF(Setup!$B$18="","",Setup!$B$18) | T23: =IF(S23="","",SUMIFS(Transaction!$E:$E,Transaction!$C:$C,"รายรับ",Transaction!$D:$D,S23,Transaction!$B:$B,">="&$T$4,Transaction!$B:$B,"<"&$T$5)) | U23: =IF(OR(S23="",N(T23)<=0),"",COUNTIF($T$11:$T$25,">"&T23)+COUNTIF($T$11:T23,T23)) | W23: =IF(Setup!$D$18="","",Setup!$D$18) | X23: =IF(W23="","",SUMIFS(Transaction!$E:$E,Transaction!$C:$C,"รายจ่าย",Transaction!$D:$D,W23,Transaction!$B:$B,">="&$T$4,Transaction!$B:$B,"<"&$T$5)) | Y23: =IF(OR(W23="",N(X23)<=0),"",COUNTIF($X$11:$X$35,">"&X23)+COUNTIF($X$11:X23,X23)) | AA23: =IF(Setup!$F$18="","",Setup!$F$18) | AB23: =IF(AA23="","",SUMIFS(Transaction!$E:$E,Transaction!$C:$C,"เงินออม",Transaction!$D:$D,AA23,Transaction!$B:$B,">="&$T$4,Transaction!$B:$B,"<"&$T$5)) | AC23: =IF(OR(AA23="",N(AB23)<=0),"",COUNTIF($AB$11:$AB$25,">"&AB23)+COUNTIF($AB$11:AB23,AB23))
B24: รายจ่ายก้อนใหญ่สุดของเดือน | C24: =_xlfn.MAXIFS(Transaction!$E:$E,Transaction!$C:$C,"รายจ่าย",Transaction!$B:$B,">="&$T$4,Transaction!$B:$B,"<"&$T$5) | S24: =IF(Setup!$B$19="","",Setup!$B$19) | T24: =IF(S24="","",SUMIFS(Transaction!$E:$E,Transaction!$C:$C,"รายรับ",Transaction!$D:$D,S24,Transaction!$B:$B,">="&$T$4,Transaction!$B:$B,"<"&$T$5)) | U24: =IF(OR(S24="",N(T24)<=0),"",COUNTIF($T$11:$T$25,">"&T24)+COUNTIF($T$11:T24,T24)) | W24: =IF(Setup!$D$19="","",Setup!$D$19) | X24: =IF(W24="","",SUMIFS(Transaction!$E:$E,Transaction!$C:$C,"รายจ่าย",Transaction!$D:$D,W24,Transaction!$B:$B,">="&$T$4,Transaction!$B:$B,"<"&$T$5)) | Y24: =IF(OR(W24="",N(X24)<=0),"",COUNTIF($X$11:$X$35,">"&X24)+COUNTIF($X$11:X24,X24)) | AA24: =IF(Setup!$F$19="","",Setup!$F$19) | AB24: =IF(AA24="","",SUMIFS(Transaction!$E:$E,Transaction!$C:$C,"เงินออม",Transaction!$D:$D,AA24,Transaction!$B:$B,">="&$T$4,Transaction!$B:$B,"<"&$T$5)) | AC24: =IF(OR(AA24="",N(AB24)<=0),"",COUNTIF($AB$11:$AB$25,">"&AB24)+COUNTIF($AB$11:AB24,AB24))
B25: หมวดที่ใช้จ่ายมากที่สุด | C25: =IFERROR(INDEX($W$11:$W$35,MATCH(1,$Y$11:$Y$35,0)),"-") | S25: =IF(Setup!$B$20="","",Setup!$B$20) | T25: =IF(S25="","",SUMIFS(Transaction!$E:$E,Transaction!$C:$C,"รายรับ",Transaction!$D:$D,S25,Transaction!$B:$B,">="&$T$4,Transaction!$B:$B,"<"&$T$5)) | U25: =IF(OR(S25="",N(T25)<=0),"",COUNTIF($T$11:$T$25,">"&T25)+COUNTIF($T$11:T25,T25)) | W25: =IF(Setup!$D$20="","",Setup!$D$20) | X25: =IF(W25="","",SUMIFS(Transaction!$E:$E,Transaction!$C:$C,"รายจ่าย",Transaction!$D:$D,W25,Transaction!$B:$B,">="&$T$4,Transaction!$B:$B,"<"&$T$5)) | Y25: =IF(OR(W25="",N(X25)<=0),"",COUNTIF($X$11:$X$35,">"&X25)+COUNTIF($X$11:X25,X25)) | AA25: =IF(Setup!$F$20="","",Setup!$F$20) | AB25: =IF(AA25="","",SUMIFS(Transaction!$E:$E,Transaction!$C:$C,"เงินออม",Transaction!$D:$D,AA25,Transaction!$B:$B,">="&$T$4,Transaction!$B:$B,"<"&$T$5)) | AC25: =IF(OR(AA25="",N(AB25)<=0),"",COUNTIF($AB$11:$AB$25,">"&AB25)+COUNTIF($AB$11:AB25,AB25))
S26: รวม | T26: =SUM(T11:T25) | W26: =IF(Setup!$D$21="","",Setup!$D$21) | X26: =IF(W26="","",SUMIFS(Transaction!$E:$E,Transaction!$C:$C,"รายจ่าย",Transaction!$D:$D,W26,Transaction!$B:$B,">="&$T$4,Transaction!$B:$B,"<"&$T$5)) | Y26: =IF(OR(W26="",N(X26)<=0),"",COUNTIF($X$11:$X$35,">"&X26)+COUNTIF($X$11:X26,X26)) | AA26: รวม | AB26: =SUM(AB11:AB25)
W27: =IF(Setup!$D$22="","",Setup!$D$22) | X27: =IF(W27="","",SUMIFS(Transaction!$E:$E,Transaction!$C:$C,"รายจ่าย",Transaction!$D:$D,W27,Transaction!$B:$B,">="&$T$4,Transaction!$B:$B,"<"&$T$5)) | Y27: =IF(OR(W27="",N(X27)<=0),"",COUNTIF($X$11:$X$35,">"&X27)+COUNTIF($X$11:X27,X27))
B28: 🥧 สัดส่วนตามหมวดหมู่ & Top 10 ของเดือนนี้ | W28: =IF(Setup!$D$23="","",Setup!$D$23) | X28: =IF(W28="","",SUMIFS(Transaction!$E:$E,Transaction!$C:$C,"รายจ่าย",Transaction!$D:$D,W28,Transaction!$B:$B,">="&$T$4,Transaction!$B:$B,"<"&$T$5)) | Y28: =IF(OR(W28="",N(X28)<=0),"",COUNTIF($X$11:$X$35,">"&X28)+COUNTIF($X$11:X28,X28))
W29: =IF(Setup!$D$24="","",Setup!$D$24) | X29: =IF(W29="","",SUMIFS(Transaction!$E:$E,Transaction!$C:$C,"รายจ่าย",Transaction!$D:$D,W29,Transaction!$B:$B,">="&$T$4,Transaction!$B:$B,"<"&$T$5)) | Y29: =IF(OR(W29="",N(X29)<=0),"",COUNTIF($X$11:$X$35,">"&X29)+COUNTIF($X$11:X29,X29))
W30: =IF(Setup!$D$25="","",Setup!$D$25) | X30: =IF(W30="","",SUMIFS(Transaction!$E:$E,Transaction!$C:$C,"รายจ่าย",Transaction!$D:$D,W30,Transaction!$B:$B,">="&$T$4,Transaction!$B:$B,"<"&$T$5)) | Y30: =IF(OR(W30="",N(X30)<=0),"",COUNTIF($X$11:$X$35,">"&X30)+COUNTIF($X$11:X30,X30))
W31: =IF(Setup!$D$26="","",Setup!$D$26) | X31: =IF(W31="","",SUMIFS(Transaction!$E:$E,Transaction!$C:$C,"รายจ่าย",Transaction!$D:$D,W31,Transaction!$B:$B,">="&$T$4,Transaction!$B:$B,"<"&$T$5)) | Y31: =IF(OR(W31="",N(X31)<=0),"",COUNTIF($X$11:$X$35,">"&X31)+COUNTIF($X$11:X31,X31))
W32: =IF(Setup!$D$27="","",Setup!$D$27) | X32: =IF(W32="","",SUMIFS(Transaction!$E:$E,Transaction!$C:$C,"รายจ่าย",Transaction!$D:$D,W32,Transaction!$B:$B,">="&$T$4,Transaction!$B:$B,"<"&$T$5)) | Y32: =IF(OR(W32="",N(X32)<=0),"",COUNTIF($X$11:$X$35,">"&X32)+COUNTIF($X$11:X32,X32))
W33: =IF(Setup!$D$28="","",Setup!$D$28) | X33: =IF(W33="","",SUMIFS(Transaction!$E:$E,Transaction!$C:$C,"รายจ่าย",Transaction!$D:$D,W33,Transaction!$B:$B,">="&$T$4,Transaction!$B:$B,"<"&$T$5)) | Y33: =IF(OR(W33="",N(X33)<=0),"",COUNTIF($X$11:$X$35,">"&X33)+COUNTIF($X$11:X33,X33))
W34: =IF(Setup!$D$29="","",Setup!$D$29) | X34: =IF(W34="","",SUMIFS(Transaction!$E:$E,Transaction!$C:$C,"รายจ่าย",Transaction!$D:$D,W34,Transaction!$B:$B,">="&$T$4,Transaction!$B:$B,"<"&$T$5)) | Y34: =IF(OR(W34="",N(X34)<=0),"",COUNTIF($X$11:$X$35,">"&X34)+COUNTIF($X$11:X34,X34))
W35: =IF(Setup!$D$30="","",Setup!$D$30) | X35: =IF(W35="","",SUMIFS(Transaction!$E:$E,Transaction!$C:$C,"รายจ่าย",Transaction!$D:$D,W35,Transaction!$B:$B,">="&$T$4,Transaction!$B:$B,"<"&$T$5)) | Y35: =IF(OR(W35="",N(X35)<=0),"",COUNTIF($X$11:$X$35,">"&X35)+COUNTIF($X$11:X35,X35))
W36: รวม | X36: =SUM(X11:X35)
S39: ข้อมูลประกอบกราฟ
S40: กราฟ: รายรับ | T40: จำนวนเงิน | W40: กราฟ: รายจ่าย | X40: จำนวนเงิน | AA40: กราฟ: เงินออม | AB40: จำนวนเงิน
S41: =IFERROR(INDEX($S$11:$S$25,MATCH(1,$U$11:$U$25,0)),"") | T41: =IFERROR(INDEX($T$11:$T$25,MATCH(1,$U$11:$U$25,0)),"") | W41: =IFERROR(INDEX($W$11:$W$35,MATCH(1,$Y$11:$Y$35,0)),"") | X41: =IFERROR(INDEX($X$11:$X$35,MATCH(1,$Y$11:$Y$35,0)),"") | AA41: =IFERROR(INDEX($AA$11:$AA$25,MATCH(1,$AC$11:$AC$25,0)),"") | AB41: =IFERROR(INDEX($AB$11:$AB$25,MATCH(1,$AC$11:$AC$25,0)),"")
S42: =IFERROR(INDEX($S$11:$S$25,MATCH(2,$U$11:$U$25,0)),"") | T42: =IFERROR(INDEX($T$11:$T$25,MATCH(2,$U$11:$U$25,0)),"") | W42: =IFERROR(INDEX($W$11:$W$35,MATCH(2,$Y$11:$Y$35,0)),"") | X42: =IFERROR(INDEX($X$11:$X$35,MATCH(2,$Y$11:$Y$35,0)),"") | AA42: =IFERROR(INDEX($AA$11:$AA$25,MATCH(2,$AC$11:$AC$25,0)),"") | AB42: =IFERROR(INDEX($AB$11:$AB$25,MATCH(2,$AC$11:$AC$25,0)),"")
S43: =IFERROR(INDEX($S$11:$S$25,MATCH(3,$U$11:$U$25,0)),"") | T43: =IFERROR(INDEX($T$11:$T$25,MATCH(3,$U$11:$U$25,0)),"") | W43: =IFERROR(INDEX($W$11:$W$35,MATCH(3,$Y$11:$Y$35,0)),"") | X43: =IFERROR(INDEX($X$11:$X$35,MATCH(3,$Y$11:$Y$35,0)),"") | AA43: =IFERROR(INDEX($AA$11:$AA$25,MATCH(3,$AC$11:$AC$25,0)),"") | AB43: =IFERROR(INDEX($AB$11:$AB$25,MATCH(3,$AC$11:$AC$25,0)),"")
S44: =IFERROR(INDEX($S$11:$S$25,MATCH(4,$U$11:$U$25,0)),"") | T44: =IFERROR(INDEX($T$11:$T$25,MATCH(4,$U$11:$U$25,0)),"") | W44: =IFERROR(INDEX($W$11:$W$35,MATCH(4,$Y$11:$Y$35,0)),"") | X44: =IFERROR(INDEX($X$11:$X$35,MATCH(4,$Y$11:$Y$35,0)),"") | AA44: =IFERROR(INDEX($AA$11:$AA$25,MATCH(4,$AC$11:$AC$25,0)),"") | AB44: =IFERROR(INDEX($AB$11:$AB$25,MATCH(4,$AC$11:$AC$25,0)),"")
...

Sheet Transaction
B2: 🧾 Transaction — บันทึกรายรับ รายจ่าย เงินออม
B3: กรอกทีละแถว: วันที่ → ประเภท (Drop-down) → หมวดหมู่ (Drop-down) → จำนวนเงิน → รายละเอียด · คอลัมน์ 'ตรวจสอบ' ระบบเช็กให้อัตโนมัติ · ข้อมูลตัวอย่างลบได้ทันที (ลบเฉพาะคอลัมน์ B–F) · แถวไม่พอ: เพิ่มแถวท้ายชีต แล้วคัดลอกแถวสุดท้าย (B–G) วางลงไป
B4: ="📌 บันทึกแล้ว "&TEXT(COUNTIF($C:$C,"รายรับ")+COUNTIF($C:$C,"รายจ่าย")+COUNTIF($C:$C,"เงินออม"),"#,##0")&" รายการ ⚠ ต้องแก้ไข "&COUNTIF($G:$G,"⚠*")&" รายการ (ระบบนับทุกแถว ไม่จำกัดจำนวน)"
B5: วันที่ | C5: ประเภท | D5: หมวดหมู่ | E5: จำนวนเงิน (บาท) | F5: รายละเอียด | G5: ตรวจสอบ
B6: 46023 | C6: รายจ่าย | D6: ค่าที่พัก/ค่าเช่า | E6: 8500 | F6: ค่าเช่าคอนโด | G6: =IF(COUNTA(B6:E6)=0,"",IF(COUNTA(B6:E6)<4,"⚠ กรอกไม่ครบ",IF(NOT(ISNUMBER(B6)),"⚠ วันที่ไม่ถูกต้อง",IF(COUNTIFS(Setup!$L$6:$L$60,D6,Setup!$M$6:$M$60,C6)=0,"⚠ หมวดไม่ตรงประเภท","✓"))))
B7: 46024 | C7: รายจ่าย | D7: ค่าเดินทาง | E7: 800 | F7: เติมเงินบัตร BTS/MRT | G7: =IF(COUNTA(B7:E7)=0,"",IF(COUNTA(B7:E7)<4,"⚠ กรอกไม่ครบ",IF(NOT(ISNUMBER(B7)),"⚠ วันที่ไม่ถูกต้อง",IF(COUNTIFS(Setup!$L$6:$L$60,D7,Setup!$M$6:$M$60,C7)=0,"⚠ หมวดไม่ตรงประเภท","✓"))))
B8: 46025 | C8: รายจ่าย | D8: ค่าอาหาร | E8: 1840 | F8: ค่าอาหาร-กาแฟ สัปดาห์ที่ 1 | G8: =IF(COUNTA(B8:E8)=0,"",IF(COUNTA(B8:E8)<4,"⚠ กรอกไม่ครบ",IF(NOT(ISNUMBER(B8)),"⚠ วันที่ไม่ถูกต้อง",IF(COUNTIFS(Setup!$L$6:$L$60,D8,Setup!$M$6:$M$60,C8)=0,"⚠ หมวดไม่ตรงประเภท","✓"))))
B9: 46027 | C9: รายจ่าย | D9: ค่าน้ำ-ค่าไฟ | E9: 1050 | F9: ค่าไฟ + ค่าน้ำ | G9: =IF(COUNTA(B9:E9)=0,"",IF(COUNTA(B9:E9)<4,"⚠ กรอกไม่ครบ",IF(NOT(ISNUMBER(B9)),"⚠ วันที่ไม่ถูกต้อง",IF(COUNTIFS(Setup!$L$6:$L$60,D9,Setup!$M$6:$M$60,C9)=0,"⚠ หมวดไม่ตรงประเภท","✓"))))
B10: 46030 | C10: รายจ่าย | D10: Subscription | E10: 419 | F10: Netflix | G10: =IF(COUNTA(B10:E10)=0,"",IF(COUNTA(B10:E10)<4,"⚠ กรอกไม่ครบ",IF(NOT(ISNUMBER(B10)),"⚠ วันที่ไม่ถูกต้อง",IF(COUNTIFS(Setup!$L$6:$L$60,D10,Setup!$M$6:$M$60,C10)=0,"⚠ หมวดไม่ตรงประเภท","✓"))))
B11: 46032 | C11: รายจ่าย | D11: ค่าโทรศัพท์/เน็ต | E11: 599 | F11: ค่าโทรศัพท์รายเดือน | G11: =IF(COUNTA(B11:E11)=0,"",IF(COUNTA(B11:E11)<4,"⚠ กรอกไม่ครบ",IF(NOT(ISNUMBER(B11)),"⚠ วันที่ไม่ถูกต้อง",IF(COUNTIFS(Setup!$L$6:$L$60,D11,Setup!$M$6:$M$60,C11)=0,"⚠ หมวดไม่ตรงประเภท","✓"))))
B12: 46032 | C12: รายจ่าย | D12: ค่าอาหาร | E12: 1850 | F12: ค่าอาหาร-กาแฟ สัปดาห์ที่ 2 | G12: =IF(COUNTA(B12:E12)=0,"",IF(COUNTA(B12:E12)<4,"⚠ กรอกไม่ครบ",IF(NOT(ISNUMBER(B12)),"⚠ วันที่ไม่ถูกต้อง",IF(COUNTIFS(Setup!$L$6:$L$60,D12,Setup!$M$6:$M$60,C12)=0,"⚠ หมวดไม่ตรงประเภท","✓"))))
B13: 46034 | C13: รายจ่าย | D13: ค่าโทรศัพท์/เน็ต | E13: 590 | F13: อินเทอร์เน็ตบ้าน | G13: =IF(COUNTA(B13:E13)=0,"",IF(COUNTA(B13:E13)<4,"⚠ กรอกไม่ครบ",IF(NOT(ISNUMBER(B13)),"⚠ วันที่ไม่ถูกต้อง",IF(COUNTIFS(Setup!$L$6:$L$60,D13,Setup!$M$6:$M$60,C13)=0,"⚠ หมวดไม่ตรงประเภท","✓"))))
B14: 46034 | C14: รายจ่าย | D14: ช้อปปิ้ง | E14: 450 | F14: เสื้อผ้า | G14: =IF(COUNTA(B14:E14)=0,"",IF(COUNTA(B14:E14)<4,"⚠ กรอกไม่ครบ",IF(NOT(ISNUMBER(B14)),"⚠ วันที่ไม่ถูกต้อง",IF(COUNTIFS(Setup!$L$6:$L$60,D14,Setup!$M$6:$M$60,C14)=0,"⚠ หมวดไม่ตรงประเภท","✓"))))
B15: 46035 | C15: รายจ่าย | D15: ของใช้ในบ้าน | E15: 860 | F15: ของใช้ในบ้าน/ห้องน้ำ | G15: =IF(COUNTA(B15:E15)=0,"",IF(COUNTA(B15:E15)<4,"⚠ กรอกไม่ครบ",IF(NOT(ISNUMBER(B15)),"⚠ วันที่ไม่ถูกต้อง",IF(COUNTIFS(Setup!$L$6:$L$60,D15,Setup!$M$6:$M$60,C15)=0,"⚠ หมวดไม่ตรงประเภท","✓"))))
B16: 46035 | C16: รายจ่าย | D16: สังสรรค์/บันเทิง | E16: 1130 | F16: ดูหนัง | G16: =IF(COUNTA(B16:E16)=0,"",IF(COUNTA(B16:E16)<4,"⚠ กรอกไม่ครบ",IF(NOT(ISNUMBER(B16)),"⚠ วันที่ไม่ถูกต้อง",IF(COUNTIFS(Setup!$L$6:$L$60,D16,Setup!$M$6:$M$60,C16)=0,"⚠ หมวดไม่ตรงประเภท","✓"))))
B17: 46037 | C17: รายรับ | D17: โบนัส | E17: 63000 | F17: โบนัสประจำปี | G17: =IF(COUNTA(B17:E17)=0,"",IF(COUNTA(B17:E17)<4,"⚠ กรอกไม่ครบ",IF(NOT(ISNUMBER(B17)),"⚠ วันที่ไม่ถูกต้อง",IF(COUNTIFS(Setup!$L$6:$L$60,D17,Setup!$M$6:$M$60,C17)=0,"⚠ หมวดไม่ตรงประเภท","✓"))))
... B263: 46295 | C263: รายรับ | D263: ดอกเบี้ย/ปันผล | E263: 880 | F263: ดอกเบี้ยบัญชีออมทรัพย์ | G263: =IF(COUNTA(B263:E263)=0,"",IF(COUNTA(B263:E263)<4,"⚠ กรอกไม่ครบ",IF(NOT(ISNUMBER(B263)),"⚠ วันที่ไม่ถูกต้อง",IF(COUNTIFS(Setup!$L$6:$L$60,D263,Setup!$M$6:$M$60,C263)=0,"⚠ หมวดไม่ตรงประเภท","✓"))))
G264: =IF(COUNTA(B264:E264)=0,"",IF(COUNTA(B264:E264)<4,"⚠ กรอกไม่ครบ",IF(NOT(ISNUMBER(B264)),"⚠ วันที่ไม่ถูกต้อง",IF(COUNTIFS(Setup!$L$6:$L$60,D264,Setup!$M$6:$M$60,C264)=0,"⚠ หมวดไม่ตรงประเภท","✓"))))
G265: =IF(COUNTA(B265:E265)=0,"",IF(COUNTA(B265:E265)<4,"⚠ กรอกไม่ครบ",IF(NOT(ISNUMBER(B265)),"⚠ วันที่ไม่ถูกต้อง",IF(COUNTIFS(Setup!$L$6:$L$60,D265,Setup!$M$6:$M$60,C265)=0,"⚠ หมวดไม่ตรงประเภท","✓"))))
G266: =IF(COUNTA(B266:E266)=0,"",IF(COUNTA(B266:E266)<4,"⚠ กรอกไม่ครบ",IF(NOT(ISNUMBER(B266)),"⚠ วันที่ไม่ถูกต้อง",IF(COUNTIFS(Setup!$L$6:$L$60,D266,Setup!$M$6:$M$60,C266)=0,"⚠ หมวดไม่ตรงประเภท","✓"))))
G267: =IF(COUNTA(B267:E267)=0,"",IF(COUNTA(B267:E267)<4,"⚠ กรอกไม่ครบ",IF(NOT(ISNUMBER(B267)),"⚠ วันที่ไม่ถูกต้อง",IF(COUNTIFS(Setup!$L$6:$L$60,D267,Setup!$M$6:$M$60,C267)=0,"⚠ หมวดไม่ตรงประเภท","✓"))))
G268: =IF(COUNTA(B268:E268)=0,"",IF(COUNTA(B268:E268)<4,"⚠ กรอกไม่ครบ",IF(NOT(ISNUMBER(B268)),"⚠ วันที่ไม่ถูกต้อง",IF(COUNTIFS(Setup!$L$6:$L$60,D268,Setup!$M$6:$M$60,C268)=0,"⚠ หมวดไม่ตรงประเภท","✓"))))
G269: =IF(COUNTA(B269:E269)=0,"",IF(COUNTA(B269:E269)<4,"⚠ กรอกไม่ครบ",IF(NOT(ISNUMBER(B269)),"⚠ วันที่ไม่ถูกต้อง",IF(COUNTIFS(Setup!$L$6:$L$60,D269,Setup!$M$6:$M$60,C269)=0,"⚠ หมวดไม่ตรงประเภท","✓"))))
G270: =IF(COUNTA(B270:E270)=0,"",IF(COUNTA(B270:E270)<4,"⚠ กรอกไม่ครบ",IF(NOT(ISNUMBER(B270)),"⚠ วันที่ไม่ถูกต้อง",IF(COUNTIFS(Setup!$L$6:$L$60,D270,Setup!$M$6:$M$60,C270)=0,"⚠ หมวดไม่ตรงประเภท","✓"))))
G271: =IF(COUNTA(B271:E271)=0,"",IF(COUNTA(B271:E271)<4,"⚠ กรอกไม่ครบ",IF(NOT(ISNUMBER(B271)),"⚠ วันที่ไม่ถูกต้อง",IF(COUNTIFS(Setup!$L$6:$L$60,D271,Setup!$M$6:$M$60,C271)=0,"⚠ หมวดไม่ตรงประเภท","✓"))))
G272: =IF(COUNTA(B272:E272)=0,"",IF(COUNTA(B272:E272)<4,"⚠ กรอกไม่ครบ",IF(NOT(ISNUMBER(B272)),"⚠ วันที่ไม่ถูกต้อง",IF(COUNTIFS(Setup!$L$6:$L$60,D272,Setup!$M$6:$M$60,C272)=0,"⚠ หมวดไม่ตรงประเภท","✓"))))
G273: =IF(COUNTA(B273:E273)=0,"",IF(COUNTA(B273:E273)<4,"⚠ กรอกไม่ครบ",IF(NOT(ISNUMBER(B273)),"⚠ วันที่ไม่ถูกต้อง",IF(COUNTIFS(Setup!$L$6:$L$60,D273,Setup!$M$6:$M$60,C273)=0,"⚠ หมวดไม่ตรงประเภท","✓"))))
G274: =IF(COUNTA(B274:E274)=0,"",IF(COUNTA(B274:E274)<4,"⚠ กรอกไม่ครบ",IF(NOT(ISNUMBER(B274)),"⚠ วันที่ไม่ถูกต้อง",IF(COUNTIFS(Setup!$L$6:$L$60,D274,Setup!$M$6:$M$60,C274)=0,"⚠ หมวดไม่ตรงประเภท","✓"))))
G275: =IF(COUNTA(B275:E275)=0,"",IF(COUNTA(B275:E275)<4,"⚠ กรอกไม่ครบ",IF(NOT(ISNUMBER(B275)),"⚠ วันที่ไม่ถูกต้อง",IF(COUNTIFS(Setup!$L$6:$L$60,D275,Setup!$M$6:$M$60,C275)=0,"⚠ หมวดไม่ตรงประเภท","✓"))))
... G5005: =IF(COUNTA(B5005:E5005)=0,"",IF(COUNTA(B5005:E5005)<4,"⚠ กรอกไม่ครบ",IF(NOT(ISNUMBER(B5005)),"⚠ วันที่ไม่ถูกต้อง",IF(COUNTIFS(Setup!$L$6:$L$60,D5005,Setup!$M$6:$M$60,C5005)=0,"⚠ หมวดไม่ตรงประเภท","✓"))))

Sheet Setup
B2: 🧾 Setup — ตั้งค่าหมวดหมู่รายรับ รายจ่าย เงินออม
B3: พิมพ์ชื่อหมวดหมู่ในช่องสีเหลือง เพิ่มหมวดใหม่ต่อท้ายได้เลย (ห้ามเว้นแถวว่างคั่นกลาง) · ระบบจะนำไปทำ Drop-down ในหน้า Transaction และสรุปใน Dashboard อัตโนมัติ
H4: ⚙️ ข้อมูลระบบ (ไม่ต้องแก้ไข)
B5: ="💰 หมวดหมู่รายรับ ("&COUNTA(B6:B20)&"/15)" | D5: ="💸 หมวดหมู่รายจ่าย ("&COUNTA(D6:D30)&"/25)" | F5: ="🏦 หมวดหมู่เงินออม ("&COUNTA(F6:F20)&"/15)" | H5: ปี (ค.ศ.) | I5: เดือน | J5: ย่อ | L5: รายการหมวดหมู่รวม (ใช้ทำ Drop-down) | M5: ประเภท
B6: เงินเดือน | D6: ค่าอาหาร | F6: เงินฝากออมทรัพย์ | H6: 2024 | I6: มกราคม | J6: ม.ค. | L6: =IF(1<=COUNTA($B$6:$B$20),INDEX($B$6:$B$20,1),IF(1<=COUNTA($B$6:$B$20)+COUNTA($D$6:$D$30),INDEX($D$6:$D$30,1-COUNTA($B$6:$B$20)),IF(1<=COUNTA($B$6:$B$20)+COUNTA($D$6:$D$30)+COUNTA($F$6:$F$20),INDEX($F$6:$F$20,1-COUNTA($B$6:$B$20)-COUNTA($D$6:$D$30)),""))) | M6: =IF(1<=COUNTA($B$6:$B$20),"รายรับ",IF(1<=COUNTA($B$6:$B$20)+COUNTA($D$6:$D$30),"รายจ่าย",IF(1<=COUNTA($B$6:$B$20)+COUNTA($D$6:$D$30)+COUNTA($F$6:$F$20),"เงินออม","")))
B7: โบนัส | D7: ค่าเดินทาง | F7: เงินสำรองฉุกเฉิน | H7: 2025 | I7: กุมภาพันธ์ | J7: ก.พ. | L7: =IF(2<=COUNTA($B$6:$B$20),INDEX($B$6:$B$20,2),IF(2<=COUNTA($B$6:$B$20)+COUNTA($D$6:$D$30),INDEX($D$6:$D$30,2-COUNTA($B$6:$B$20)),IF(2<=COUNTA($B$6:$B$20)+COUNTA($D$6:$D$30)+COUNTA($F$6:$F$20),INDEX($F$6:$F$20,2-COUNTA($B$6:$B$20)-COUNTA($D$6:$D$30)),""))) | M7: =IF(2<=COUNTA($B$6:$B$20),"รายรับ",IF(2<=COUNTA($B$6:$B$20)+COUNTA($D$6:$D$30),"รายจ่าย",IF(2<=COUNTA($B$6:$B$20)+COUNTA($D$6:$D$30)+COUNTA($F$6:$F$20),"เงินออม","")))
B8: ค่าล่วงเวลา (OT) | D8: ค่าที่พัก/ค่าเช่า | F8: กองทุน SSF/RMF | H8: 2026 | I8: มีนาคม | J8: มี.ค. | L8: =IF(3<=COUNTA($B$6:$B$20),INDEX($B$6:$B$20,3),IF(3<=COUNTA($B$6:$B$20)+COUNTA($D$6:$D$30),INDEX($D$6:$D$30,3-COUNTA($B$6:$B$20)),IF(3<=COUNTA($B$6:$B$20)+COUNTA($D$6:$D$30)+COUNTA($F$6:$F$20),INDEX($F$6:$F$20,3-COUNTA($B$6:$B$20)-COUNTA($D$6:$D$30)),""))) | M8: =IF(3<=COUNTA($B$6:$B$20),"รายรับ",IF(3<=COUNTA($B$6:$B$20)+COUNTA($D$6:$D$30),"รายจ่าย",IF(3<=COUNTA($B$6:$B$20)+COUNTA($D$6:$D$30)+COUNTA($F$6:$F$20),"เงินออม","")))
B9: ฟรีแลนซ์/งานเสริม | D9: ค่าน้ำ-ค่าไฟ | F9: หุ้น/ETF | H9: 2027 | I9: เมษายน | J9: เม.ย. | L9: =IF(4<=COUNTA($B$6:$B$20),INDEX($B$6:$B$20,4),IF(4<=COUNTA($B$6:$B$20)+COUNTA($D$6:$D$30),INDEX($D$6:$D$30,4-COUNTA($B$6:$B$20)),IF(4<=COUNTA($B$6:$B$20)+COUNTA($D$6:$D$30)+COUNTA($F$6:$F$20),INDEX($F$6:$F$20,4-COUNTA($B$6:$B$20)-COUNTA($D$6:$D$30)),""))) | M9: =IF(4<=COUNTA($B$6:$B$20),"รายรับ",IF(4<=COUNTA($B$6:$B$20)+COUNTA($D$6:$D$30),"รายจ่าย",IF(4<=COUNTA($B$6:$B$20)+COUNTA($D$6:$D$30)+COUNTA($F$6:$F$20),"เงินออม","")))
B10: ขายของออนไลน์ | D10: ค่าโทรศัพท์/เน็ต | F10: ออมทอง | H10: 2028 | I10: พฤษภาคม | J10: พ.ค. | L10: =IF(5<=COUNTA($B$6:$B$20),INDEX($B$6:$B$20,5),IF(5<=COUNTA($B$6:$B$20)+COUNTA($D$6:$D$30),INDEX($D$6:$D$30,5-COUNTA($B$6:$B$20)),IF(5<=COUNTA($B$6:$B$20)+COUNTA($D$6:$D$30)+COUNTA($F$6:$F$20),INDEX($F$6:$F$20,5-COUNTA($B$6:$B$20)-COUNTA($D$6:$D$30)),""))) | M10: =IF(5<=COUNTA($B$6:$B$20),"รายรับ",IF(5<=COUNTA($B$6:$B$20)+COUNTA($D$6:$D$30),"รายจ่าย",IF(5<=COUNTA($B$6:$B$20)+COUNTA($D$6:$D$30)+COUNTA($F$6:$F$20),"เงินออม","")))
B11: ดอกเบี้ย/ปันผล | D11: ของใช้ในบ้าน | F11: ออมเพื่อเกษียณ | H11: 2029 | I11: มิถุนายน | J11: มิ.ย. | L11: =IF(6<=COUNTA($B$6:$B$20),INDEX($B$6:$B$20,6),IF(6<=COUNTA($B$6:$B$20)+COUNTA($D$6:$D$30),INDEX($D$6:$D$30,6-COUNTA($B$6:$B$20)),IF(6<=COUNTA($B$6:$B$20)+COUNTA($D$6:$D$30)+COUNTA($F$6:$F$20),INDEX($F$6:$F$20,6-COUNTA($B$6:$B$20)-COUNTA($D$6:$D$30)),""))) | M11: =IF(6<=COUNTA($B$6:$B$20),"รายรับ",IF(6<=COUNTA($B$6:$B$20)+COUNTA($D$6:$D$30),"รายจ่าย",IF(6<=COUNTA($B$6:$B$20)+COUNTA($D$6:$D$30)+COUNTA($F$6:$F$20),"เงินออม","")))
B12: เงินคืนภาษี | D12: ช้อปปิ้ง | F12: ออมอื่นๆ | H12: 2030 | I12: กรกฎาคม | J12: ก.ค. | L12: =IF(7<=COUNTA($B$6:$B$20),INDEX($B$6:$B$20,7),IF(7<=COUNTA($B$6:$B$20)+COUNTA($D$6:$D$30),INDEX($D$6:$D$30,7-COUNTA($B$6:$B$20)),IF(7<=COUNTA($B$6:$B$20)+COUNTA($D$6:$D$30)+COUNTA($F$6:$F$20),INDEX($F$6:$F$20,7-COUNTA($B$6:$B$20)-COUNTA($D$6:$D$30)),""))) | M12: =IF(7<=COUNTA($B$6:$B$20),"รายรับ",IF(7<=COUNTA($B$6:$B$20)+COUNTA($D$6:$D$30),"รายจ่าย",IF(7<=COUNTA($B$6:$B$20)+COUNTA($D$6:$D$30)+COUNTA($F$6:$F$20),"เงินออม","")))
B13: รายรับอื่นๆ | D13: สุขภาพ/ยา | H13: 2031 | I13: สิงหาคม | J13: ส.ค. | L13: =IF(8<=COUNTA($B$6:$B$20),INDEX($B$6:$B$20,8),IF(8<=COUNTA($B$6:$B$20)+COUNTA($D$6:$D$30),INDEX($D$6:$D$30,8-COUNTA($B$6:$B$20)),IF(8<=COUNTA($B$6:$B$20)+COUNTA($D$6:$D$30)+COUNTA($F$6:$F$20),INDEX($F$6:$F$20,8-COUNTA($B$6:$B$20)-COUNTA($D$6:$D$30)),""))) | M13: =IF(8<=COUNTA($B$6:$B$20),"รายรับ",IF(8<=COUNTA($B$6:$B$20)+COUNTA($D$6:$D$30),"รายจ่าย",IF(8<=COUNTA($B$6:$B$20)+COUNTA($D$6:$D$30)+COUNTA($F$6:$F$20),"เงินออม","")))
D14: ประกันภัย | H14: 2032 | I14: กันยายน | J14: ก.ย. | L14: =IF(9<=COUNTA($B$6:$B$20),INDEX($B$6:$B$20,9),IF(9<=COUNTA($B$6:$B$20)+COUNTA($D$6:$D$30),INDEX($D$6:$D$30,9-COUNTA($B$6:$B$20)),IF(9<=COUNTA($B$6:$B$20)+COUNTA($D$6:$D$30)+COUNTA($F$6:$F$20),INDEX($F$6:$F$20,9-COUNTA($B$6:$B$20)-COUNTA($D$6:$D$30)),""))) | M14: =IF(9<=COUNTA($B$6:$B$20),"รายรับ",IF(9<=COUNTA($B$6:$B$20)+COUNTA($D$6:$D$30),"รายจ่าย",IF(9<=COUNTA($B$6:$B$20)+COUNTA($D$6:$D$30)+COUNTA($F$6:$F$20),"เงินออม","")))
D15: สังสรรค์/บันเทิง | H15: 2033 | I15: ตุลาคม | J15: ต.ค. | L15: =IF(10<=COUNTA($B$6:$B$20),INDEX($B$6:$B$20,10),IF(10<=COUNTA($B$6:$B$20)+COUNTA($D$6:$D$30),INDEX($D$6:$D$30,10-COUNTA($B$6:$B$20)),IF(10<=COUNTA($B$6:$B$20)+COUNTA($D$6:$D$30)+COUNTA($F$6:$F$20),INDEX($F$6:$F$20,10-COUNTA($B$6:$B$20)-COUNTA($D$6:$D$30)),""))) | M15: =IF(10<=COUNTA($B$6:$B$20),"รายรับ",IF(10<=COUNTA($B$6:$B$20)+COUNTA($D$6:$D$30),"รายจ่าย",IF(10<=COUNTA($B$6:$B$20)+COUNTA($D$6:$D$30)+COUNTA($F$6:$F$20),"เงินออม","")))
D16: การศึกษา | H16: 2034 | I16: พฤศจิกายน | J16: พ.ย. | L16: =IF(11<=COUNTA($B$6:$B$20),INDEX($B$6:$B$20,11),IF(11<=COUNTA($B$6:$B$20)+COUNTA($D$6:$D$30),INDEX($D$6:$D$30,11-COUNTA($B$6:$B$20)),IF(11<=COUNTA($B$6:$B$20)+COUNTA($D$6:$D$30)+COUNTA($F$6:$F$20),INDEX($F$6:$F$20,11-COUNTA($B$6:$B$20)-COUNTA($D$6:$D$30)),""))) | M16: =IF(11<=COUNTA($B$6:$B$20),"รายรับ",IF(11<=COUNTA($B$6:$B$20)+COUNTA($D$6:$D$30),"รายจ่าย",IF(11<=COUNTA($B$6:$B$20)+COUNTA($D$6:$D$30)+COUNTA($F$6:$F$20),"เงินออม","")))
D17: ผ่อนชำระ/หนี้ | H17: 2035 | I17: ธันวาคม | J17: ธ.ค. | L17: =IF(12<=COUNTA($B$6:$B$20),INDEX($B$6:$B$20,12),IF(12<=COUNTA($B$6:$B$20)+COUNTA($D$6:$D$30),INDEX($D$6:$D$30,12-COUNTA($B$6:$B$20)),IF(12<=COUNTA($B$6:$B$20)+COUNTA($D$6:$D$30)+COUNTA($F$6:$F$20),INDEX($F$6:$F$20,12-COUNTA($B$6:$B$20)-COUNTA($D$6:$D$30)),""))) | M17: =IF(12<=COUNTA($B$6:$B$20),"รายรับ",IF(12<=COUNTA($B$6:$B$20)+COUNTA($D$6:$D$30),"รายจ่าย",IF(12<=COUNTA($B$6:$B$20)+COUNTA($D$6:$D$30)+COUNTA($F$6:$F$20),"เงินออม","")))
D18: ให้ครอบครัว | L18: =IF(13<=COUNTA($B$6:$B$20),INDEX($B$6:$B$20,13),IF(13<=COUNTA($B$6:$B$20)+COUNTA($D$6:$D$30),INDEX($D$6:$D$30,13-COUNTA($B$6:$B$20)),IF(13<=COUNTA($B$6:$B$20)+COUNTA($D$6:$D$30)+COUNTA($F$6:$F$20),INDEX($F$6:$F$20,13-COUNTA($B$6:$B$20)-COUNTA($D$6:$D$30)),""))) | M18: =IF(13<=COUNTA($B$6:$B$20),"รายรับ",IF(13<=COUNTA($B$6:$B$20)+COUNTA($D$6:$D$30),"รายจ่าย",IF(13<=COUNTA($B$6:$B$20)+COUNTA($D$6:$D$30)+COUNTA($F$6:$F$20),"เงินออม","")))
D19: ท่องเที่ยว | L19: =IF(14<=COUNTA($B$6:$B$20),INDEX($B$6:$B$20,14),IF(14<=COUNTA($B$6:$B$20)+COUNTA($D$6:$D$30),INDEX($D$6:$D$30,14-COUNTA($B$6:$B$20)),IF(14<=COUNTA($B$6:$B$20)+COUNTA($D$6:$D$30)+COUNTA($F$6:$F$20),INDEX($F$6:$F$20,14-COUNTA($B$6:$B$20)-COUNTA($D$6:$D$30)),""))) | M19: =IF(14<=COUNTA($B$6:$B$20),"รายรับ",IF(14<=COUNTA($B$6:$B$20)+COUNTA($D$6:$D$30),"รายจ่าย",IF(14<=COUNTA($B$6:$B$20)+COUNTA($D$6:$D$30)+COUNTA($F$6:$F$20),"เงินออม","")))
D20: Subscription | L20: =IF(15<=COUNTA($B$6:$B$20),INDEX($B$6:$B$20,15),IF(15<=COUNTA($B$6:$B$20)+COUNTA($D$6:$D$30),INDEX($D$6:$D$30,15-COUNTA($B$6:$B$20)),IF(15<=COUNTA($B$6:$B$20)+COUNTA($D$6:$D$30)+COUNTA($F$6:$F$20),INDEX($F$6:$F$20,15-COUNTA($B$6:$B$20)-COUNTA($D$6:$D$30)),""))) | M20: =IF(15<=COUNTA($B$6:$B$20),"รายรับ",IF(15<=COUNTA($B$6:$B$20)+COUNTA($D$6:$D$30),"รายจ่าย",IF(15<=COUNTA($B$6:$B$20)+COUNTA($D$6:$D$30)+COUNTA($F$6:$F$20),"เงินออม","")))
D21: ทำบุญ/บริจาค | L21: =IF(16<=COUNTA($B$6:$B$20),INDEX($B$6:$B$20,16),IF(16<=COUNTA($B$6:$B$20)+COUNTA($D$6:$D$30),INDEX($D$6:$D$30,16-COUNTA($B$6:$B$20)),IF(16<=COUNTA($B$6:$B$20)+COUNTA($D$6:$D$30)+COUNTA($F$6:$F$20),INDEX($F$6:$F$20,16-COUNTA($B$6:$B$20)-COUNTA($D$6:$D$30)),""))) | M21: =IF(16<=COUNTA($B$6:$B$20),"รายรับ",IF(16<=COUNTA($B$6:$B$20)+COUNTA($D$6:$D$30),"รายจ่าย",IF(16<=COUNTA($B$6:$B$20)+COUNTA($D$6:$D$30)+COUNTA($F$6:$F$20),"เงินออม","")))
D22: รายจ่ายอื่นๆ | L22: =IF(17<=COUNTA($B$6:$B$20),INDEX($B$6:$B$20,17),IF(17<=COUNTA($B$6:$B$20)+COUNTA($D$6:$D$30),INDEX($D$6:$D$30,17-COUNTA($B$6:$B$20)),IF(17<=COUNTA($B$6:$B$20)+COUNTA($D$6:$D$30)+COUNTA($F$6:$F$20),INDEX($F$6:$F$20,17-COUNTA($B$6:$B$20)-COUNTA($D$6:$D$30)),""))) | M22: =IF(17<=COUNTA($B$6:$B$20),"รายรับ",IF(17<=COUNTA($B$6:$B$20)+COUNTA($D$6:$D$30),"รายจ่าย",IF(17<=COUNTA($B$6:$B$20)+COUNTA($D$6:$D$30)+COUNTA($F$6:$F$20),"เงินออม","")))
L23: =IF(18<=COUNTA($B$6:$B$20),INDEX($B$6:$B$20,18),IF(18<=COUNTA($B$6:$B$20)+COUNTA($D$6:$D$30),INDEX($D$6:$D$30,18-COUNTA($B$6:$B$20)),IF(18<=COUNTA($B$6:$B$20)+COUNTA($D$6:$D$30)+COUNTA($F$6:$F$20),INDEX($F$6:$F$20,18-COUNTA($B$6:$B$20)-COUNTA($D$6:$D$30)),""))) | M23: =IF(18<=COUNTA($B$6:$B$20),"รายรับ",IF(18<=COUNTA($B$6:$B$20)+COUNTA($D$6:$D$30),"รายจ่าย",IF(18<=COUNTA($B$6:$B$20)+COUNTA($D$6:$D$30)+COUNTA($F$6:$F$20),"เงินออม","")))
L24: =IF(19<=COUNTA($B$6:$B$20),INDEX($B$6:$B$20,19),IF(19<=COUNTA($B$6:$B$20)+COUNTA($D$6:$D$30),INDEX($D$6:$D$30,19-COUNTA($B$6:$B$20)),IF(19<=COUNTA($B$6:$B$20)+COUNTA($D$6:$D$30)+COUNTA($F$6:$F$20),INDEX($F$6:$F$20,19-COUNTA($B$6:$B$20)-COUNTA($D$6:$D$30)),""))) | M24: =IF(19<=COUNTA($B$6:$B$20),"รายรับ",IF(19<=COUNTA($B$6:$B$20)+COUNTA($D$6:$D$30),"รายจ่าย",IF(19<=COUNTA($B$6:$B$20)+COUNTA($D$6:$D$30)+COUNTA($F$6:$F$20),"เงินออม","")))
L25: =IF(20<=COUNTA($B$6:$B$20),INDEX($B$6:$B$20,20),IF(20<=COUNTA($B$6:$B$20)+COUNTA($D$6:$D$30),INDEX($D$6:$D$30,20-COUNTA($B$6:$B$20)),IF(20<=COUNTA($B$6:$B$20)+COUNTA($D$6:$D$30)+COUNTA($F$6:$F$20),INDEX($F$6:$F$20,20-COUNTA($B$6:$B$20)-COUNTA($D$6:$D$30)),""))) | M25: =IF(20<=COUNTA($B$6:$B$20),"รายรับ",IF(20<=COUNTA($B$6:$B$20)+COUNTA($D$6:$D$30),"รายจ่าย",IF(20<=COUNTA($B$6:$B$20)+COUNTA($D$6:$D$30)+COUNTA($F$6:$F$20),"เงินออม","")))
L26: =IF(21<=COUNTA($B$6:$B$20),INDEX($B$6:$B$20,21),IF(21<=COUNTA($B$6:$B$20)+COUNTA($D$6:$D$30),INDEX($D$6:$D$30,21-COUNTA($B$6:$B$20)),IF(21<=COUNTA($B$6:$B$20)+COUNTA($D$6:$D$30)+COUNTA($F$6:$F$20),INDEX($F$6:$F$20,21-COUNTA($B$6:$B$20)-COUNTA($D$6:$D$30)),""))) | M26: =IF(21<=COUNTA($B$6:$B$20),"รายรับ",IF(21<=COUNTA($B$6:$B$20)+COUNTA($D$6:$D$30),"รายจ่าย",IF(21<=COUNTA($B$6:$B$20)+COUNTA($D$6:$D$30)+COUNTA($F$6:$F$20),"เงินออม","")))
L27: =IF(22<=COUNTA($B$6:$B$20),INDEX($B$6:$B$20,22),IF(22<=COUNTA($B$6:$B$20)+COUNTA($D$6:$D$30),INDEX($D$6:$D$30,22-COUNTA($B$6:$B$20)),IF(22<=COUNTA($B$6:$B$20)+COUNTA($D$6:$D$30)+COUNTA($F$6:$F$20),INDEX($F$6:$F$20,22-COUNTA($B$6:$B$20)-COUNTA($D$6:$D$30)),""))) | M27: =IF(22<=COUNTA($B$6:$B$20),"รายรับ",IF(22<=COUNTA($B$6:$B$20)+COUNTA($D$6:$D$30),"รายจ่าย",IF(22<=COUNTA($B$6:$B$20)+COUNTA($D$6:$D$30)+COUNTA($F$6:$F$20),"เงินออม","")))
L28: =IF(23<=COUNTA($B$6:$B$20),INDEX($B$6:$B$20,23),IF(23<=COUNTA($B$6:$B$20)+COUNTA($D$6:$D$30),INDEX($D$6:$D$30,23-COUNTA($B$6:$B$20)),IF(23<=COUNTA($B$6:$B$20)+COUNTA($D$6:$D$30)+COUNTA($F$6:$F$20),INDEX($F$6:$F$20,23-COUNTA($B$6:$B$20)-COUNTA($D$6:$D$30)),""))) | M28: =IF(23<=COUNTA($B$6:$B$20),"รายรับ",IF(23<=COUNTA($B$6:$B$20)+COUNTA($D$6:$D$30),"รายจ่าย",IF(23<=COUNTA($B$6:$B$20)+COUNTA($D$6:$D$30)+COUNTA($F$6:$F$20),"เงินออม","")))
L29: =IF(24<=COUNTA($B$6:$B$20),INDEX($B$6:$B$20,24),IF(24<=COUNTA($B$6:$B$20)+COUNTA($D$6:$D$30),INDEX($D$6:$D$30,24-COUNTA($B$6:$B$20)),IF(24<=COUNTA($B$6:$B$20)+COUNTA($D$6:$D$30)+COUNTA($F$6:$F$20),INDEX($F$6:$F$20,24-COUNTA($B$6:$B$20)-COUNTA($D$6:$D$30)),""))) | M29: =IF(24<=COUNTA($B$6:$B$20),"รายรับ",IF(24<=COUNTA($B$6:$B$20)+COUNTA($D$6:$D$30),"รายจ่าย",IF(24<=COUNTA($B$6:$B$20)+COUNTA($D$6:$D$30)+COUNTA($F$6:$F$20),"เงินออม","")))
L30: =IF(25<=COUNTA($B$6:$B$20),INDEX($B$6:$B$20,25),IF(25<=COUNTA($B$6:$B$20)+COUNTA($D$6:$D$30),INDEX($D$6:$D$30,25-COUNTA($B$6:$B$20)),IF(25<=COUNTA($B$6:$B$20)+COUNTA($D$6:$D$30)+COUNTA($F$6:$F$20),INDEX($F$6:$F$20,25-COUNTA($B$6:$B$20)-COUNTA($D$6:$D$30)),""))) | M30: =IF(25<=COUNTA($B$6:$B$20),"รายรับ",IF(25<=COUNTA($B$6:$B$20)+COUNTA($D$6:$D$30),"รายจ่าย",IF(25<=COUNTA($B$6:$B$20)+COUNTA($D$6:$D$30)+COUNTA($F$6:$F$20),"เงินออม","")))
L31: =IF(26<=COUNTA($B$6:$B$20),INDEX($B$6:$B$20,26),IF(26<=COUNTA($B$6:$B$20)+COUNTA($D$6:$D$30),INDEX($D$6:$D$30,26-COUNTA($B$6:$B$20)),IF(26<=COUNTA($B$6:$B$20)+COUNTA($D$6:$D$30)+COUNTA($F$6:$F$20),INDEX($F$6:$F$20,26-COUNTA($B$6:$B$20)-COUNTA($D$6:$D$30)),""))) | M31: =IF(26<=COUNTA($B$6:$B$20),"รายรับ",IF(26<=COUNTA($B$6:$B$20)+COUNTA($D$6:$D$30),"รายจ่าย",IF(26<=COUNTA($B$6:$B$20)+COUNTA($D$6:$D$30)+COUNTA($F$6:$F$20),"เงินออม","")))
L32: =IF(27<=COUNTA($B$6:$B$20),INDEX($B$6:$B$20,27),IF(27<=COUNTA($B$6:$B$20)+COUNTA($D$6:$D$30),INDEX($D$6:$D$30,27-COUNTA($B$6:$B$20)),IF(27<=COUNTA($B$6:$B$20)+COUNTA($D$6:$D$30)+COUNTA($F$6:$F$20),INDEX($F$6:$F$20,27-COUNTA($B$6:$B$20)-COUNTA($D$6:$D$30)),""))) | M32: =IF(27<=COUNTA($B$6:$B$20),"รายรับ",IF(27<=COUNTA($B$6:$B$20)+COUNTA($D$6:$D$30),"รายจ่าย",IF(27<=COUNTA($B$6:$B$20)+COUNTA($D$6:$D$30)+COUNTA($F$6:$F$20),"เงินออม","")))
B33: 📘 วิธีใช้งาน | L33: =IF(28<=COUNTA($B$6:$B$20),INDEX($B$6:$B$20,28),IF(28<=COUNTA($B$6:$B$20)+COUNTA($D$6:$D$30),INDEX($D$6:$D$30,28-COUNTA($B$6:$B$20)),IF(28<=COUNTA($B$6:$B$20)+COUNTA($D$6:$D$30)+COUNTA($F$6:$F$20),INDEX($F$6:$F$20,28-COUNTA($B$6:$B$20)-COUNTA($D$6:$D$30)),""))) | M33: =IF(28<=COUNTA($B$6:$B$20),"รายรับ",IF(28<=COUNTA($B$6:$B$20)+COUNTA($D$6:$D$30),"รายจ่าย",IF(28<=COUNTA($B$6:$B$20)+COUNTA($D$6:$D$30)+COUNTA($F$6:$F$20),"เงินออม","")))
B34: 1) Setup — แก้/เพิ่มหมวดหมู่ในช่องสีเหลือง (สูงสุด: รายรับ 15 · รายจ่าย 25 · ออม 15 หมวด) | L34: =IF(29<=COUNTA($B$6:$B$20),INDEX($B$6:$B$20,29),IF(29<=COUNTA($B$6:$B$20)+COUNTA($D$6:$D$30),INDEX($D$6:$D$30,29-COUNTA($B$6:$B$20)),IF(29<=COUNTA($B$6:$B$20)+COUNTA($D$6:$D$30)+COUNTA($F$6:$F$20),INDEX($F$6:$F$20,29-COUNTA($B$6:$B$20)-COUNTA($D$6:$D$30)),""))) | M34: =IF(29<=COUNTA($B$6:$B$20),"รายรับ",IF(29<=COUNTA($B$6:$B$20)+COUNTA($D$6:$D$30),"รายจ่าย",IF(29<=COUNTA($B$6:$B$20)+COUNTA($D$6:$D$30)+COUNTA($F$6:$F$20),"เงินออม","")))
